module,execution_time (sec),success,timestamp,error,error_short
cowidev.vax.batch.argentina,3.88,True,2022-07-06T07:00:11,,
cowidev.vax.batch.australia,1.82,True,2022-07-06T07:00:09,,
cowidev.vax.batch.austria,,,2022-07-06T07:00:07,,
cowidev.vax.batch.belgium,2.05,True,2022-07-06T07:00:09,,
cowidev.vax.batch.bolivia,1.78,True,2022-07-06T07:00:09,,
cowidev.vax.batch.canada,4.56,True,2022-07-06T07:00:12,,
cowidev.vax.batch.chile,0.9,True,2022-07-06T07:00:10,,
cowidev.vax.batch.czechia,2.81,True,2022-07-06T07:00:12,,
cowidev.vax.batch.denmark,3.56,True,2022-07-06T07:00:13,,
cowidev.vax.batch.ecdc,40.05,False,2022-07-06T07:03:28,"Traceback (most recent call last):
  File ""/mnt/owid_live_covid/covid-19-data/scripts/venv/lib/python3.9/site-packages/urllib3/connection.py"", line 174, in _new_conn
    conn = connection.create_connection(
  File ""/mnt/owid_live_covid/covid-19-data/scripts/venv/lib/python3.9/site-packages/urllib3/util/connection.py"", line 96, in create_connection
    raise err
  File ""/mnt/owid_live_covid/covid-19-data/scripts/venv/lib/python3.9/site-packages/urllib3/util/connection.py"", line 86, in create_connection
    sock.connect(sa)
socket.timeout: timed out

During handling of the above exception, another exception occurred:

Traceback (most recent call last):
  File ""/mnt/owid_live_covid/covid-19-data/scripts/venv/lib/python3.9/site-packages/urllib3/connectionpool.py"", line 699, in urlopen
    httplib_response = self._make_request(
  File ""/mnt/owid_live_covid/covid-19-data/scripts/venv/lib/python3.9/site-packages/urllib3/connectionpool.py"", line 382, in _make_request
    self._validate_conn(conn)
  File ""/mnt/owid_live_covid/covid-19-data/scripts/venv/lib/python3.9/site-packages/urllib3/connectionpool.py"", line 1010, in _validate_conn
    conn.connect()
  File ""/mnt/owid_live_covid/covid-19-data/scripts/venv/lib/python3.9/site-packages/urllib3/connection.py"", line 358, in connect
    conn = self._new_conn()
  File ""/mnt/owid_live_covid/covid-19-data/scripts/venv/lib/python3.9/site-packages/urllib3/connection.py"", line 179, in _new_conn
    raise ConnectTimeoutError(
urllib3.exceptions.ConnectTimeoutError: (<urllib3.connection.HTTPSConnection object at 0x7f529dd56430>, 'Connection to opendata.ecdc.europa.eu timed out. (connect timeout=20)')

During handling of the above exception, another exception occurred:

Traceback (most recent call last):
  File ""/mnt/owid_live_covid/covid-19-data/scripts/venv/lib/python3.9/site-packages/requests/adapters.py"", line 440, in send
    resp = conn.urlopen(
  File ""/mnt/owid_live_covid/covid-19-data/scripts/venv/lib/python3.9/site-packages/urllib3/connectionpool.py"", line 755, in urlopen
    retries = retries.increment(
  File ""/mnt/owid_live_covid/covid-19-data/scripts/venv/lib/python3.9/site-packages/urllib3/util/retry.py"", line 574, in increment
    raise MaxRetryError(_pool, url, error or ResponseError(cause))
urllib3.exceptions.MaxRetryError: HTTPSConnectionPool(host='opendata.ecdc.europa.eu', port=443): Max retries exceeded with url: /covid19/vaccine_tracker/csv/data.csv (Caused by ConnectTimeoutError(<urllib3.connection.HTTPSConnection object at 0x7f529dd56430>, 'Connection to opendata.ecdc.europa.eu timed out. (connect timeout=20)'))

During handling of the above exception, another exception occurred:

Traceback (most recent call last):
  File ""/mnt/owid_live_covid/covid-19-data/scripts/src/cowidev/cmd/commons/get.py"", line 47, in run
    module.main()
  File ""/mnt/owid_live_covid/covid-19-data/scripts/src/cowidev/vax/batch/ecdc.py"", line 499, in main
    ECDC().export()
  File ""/mnt/owid_live_covid/covid-19-data/scripts/src/cowidev/vax/batch/ecdc.py"", line 489, in export
    df = self.read().pipe(self.pipe_base)
  File ""/mnt/owid_live_covid/covid-19-data/scripts/src/cowidev/vax/batch/ecdc.py"", line 111, in read
    df = read_csv_from_url(self.source_url, timeout=20)
  File ""/mnt/owid_live_covid/covid-19-data/scripts/src/cowidev/utils/web/download.py"", line 39, in read_csv_from_url
    download_file_from_url(url, tmp.name, timeout=timeout, verify=verify, ciphers_low=ciphers_low)
  File ""/mnt/owid_live_covid/covid-19-data/scripts/src/cowidev/utils/web/download.py"", line 52, in download_file_from_url
    r = requests.get(url, stream=True, timeout=timeout, verify=verify)
  File ""/mnt/owid_live_covid/covid-19-data/scripts/venv/lib/python3.9/site-packages/requests/api.py"", line 75, in get
    return request('get', url, params=params, **kwargs)
  File ""/mnt/owid_live_covid/covid-19-data/scripts/venv/lib/python3.9/site-packages/requests/api.py"", line 61, in request
    return session.request(method=method, url=url, **kwargs)
  File ""/mnt/owid_live_covid/covid-19-data/scripts/venv/lib/python3.9/site-packages/requests/sessions.py"", line 529, in request
    resp = self.send(prep, **send_kwargs)
  File ""/mnt/owid_live_covid/covid-19-data/scripts/venv/lib/python3.9/site-packages/requests/sessions.py"", line 645, in send
    r = adapter.send(request, **kwargs)
  File ""/mnt/owid_live_covid/covid-19-data/scripts/venv/lib/python3.9/site-packages/requests/adapters.py"", line 507, in send
    raise ConnectTimeout(e, request=request)
requests.exceptions.ConnectTimeout: HTTPSConnectionPool(host='opendata.ecdc.europa.eu', port=443): Max retries exceeded with url: /covid19/vaccine_tracker/csv/data.csv (Caused by ConnectTimeoutError(<urllib3.connection.HTTPSConnection object at 0x7f529dd56430>, 'Connection to opendata.ecdc.europa.eu timed out. (connect timeout=20)'))
","HTTPSConnectionPool(host='opendata.ecdc.europa.eu', port=443): Max retries exceeded with url: /covid19/vaccine_tracker/csv/data.csv (Caused by ConnectTimeoutError(<urllib3.connection.HTTPSConnection object at 0x7f529dd56430>, 'Connection to opendata.ecdc.europa.eu timed out. (connect timeout=20)'))"
cowidev.vax.batch.ecuador,1.38,True,2022-07-06T07:00:13,,
cowidev.vax.batch.estonia,0.7,True,2022-07-06T07:00:13,,
cowidev.vax.batch.france,0.59,True,2022-07-06T07:00:12,,
cowidev.vax.batch.germany,1.51,True,2022-07-06T07:00:14,,
cowidev.vax.batch.greece,2.55,True,2022-07-06T07:00:15,,
cowidev.vax.batch.hong_kong,9.38,True,2022-07-06T07:00:22,,
cowidev.vax.batch.indonesia,,,2022-07-06T07:00:13,,
cowidev.vax.batch.ireland,0.46,True,2022-07-06T07:00:13,,
cowidev.vax.batch.israel,6.34,True,2022-07-06T07:00:20,,
cowidev.vax.batch.italy,7.73,True,2022-07-06T07:00:22,,
cowidev.vax.batch.japan,37.51,True,2022-07-06T07:00:53,,
cowidev.vax.batch.jersey,1.82,True,2022-07-06T07:00:21,,
cowidev.vax.batch.latvia,20.63,True,2022-07-06T07:00:42,,
cowidev.vax.batch.lithuania,1.06,True,2022-07-06T07:00:23,,
cowidev.vax.batch.luxembourg,2.24,True,2022-07-06T07:00:24,,
cowidev.vax.batch.malaysia,2.47,True,2022-07-06T07:00:25,,
cowidev.vax.batch.malta,1.23,True,2022-07-06T07:00:25,,
cowidev.vax.batch.netherlands,,,2022-07-06T07:00:25,,
cowidev.vax.batch.new_zealand,23.3,True,2022-07-06T07:00:49,,
cowidev.vax.batch.norway,1.78,True,2022-07-06T07:00:27,,
cowidev.vax.batch.peru,3.22,True,2022-07-06T07:00:30,,
cowidev.vax.batch.portugal,,,2022-07-06T07:00:30,,
cowidev.vax.batch.romania,20.1,True,2022-07-06T07:00:50,,
cowidev.vax.batch.saudi_arabia,8.68,True,2022-07-06T07:00:51,,
cowidev.vax.batch.singapore,2.49,True,2022-07-06T07:00:51,,
cowidev.vax.batch.slovakia,28.68,True,2022-07-06T07:01:19,,
cowidev.vax.batch.slovenia,1.2,True,2022-07-06T07:00:52,,
cowidev.vax.batch.south_korea,28.57,True,2022-07-06T07:01:19,,
cowidev.vax.batch.spc,18.52,True,2022-07-06T07:01:10,,
cowidev.vax.batch.sweden,9.3,True,2022-07-06T07:01:01,,
cowidev.vax.batch.switzerland,35.56,True,2022-07-06T07:01:28,,
cowidev.vax.batch.trinidad_and_tobago,1.56,True,2022-07-06T07:01:03,,
cowidev.vax.batch.ukraine,,,2022-07-06T07:01:03,,
cowidev.vax.batch.united_kingdom,9.03,True,2022-07-06T07:01:12,,
cowidev.vax.batch.united_states,14.23,True,2022-07-06T07:01:24,,
cowidev.vax.batch.uruguay,3.7,True,2022-07-06T07:01:15,,
cowidev.vax.batch.zimbabwe,0.8,True,2022-07-06T07:01:16,,
cowidev.vax.incremental.africacdc,,,2022-07-06T07:01:16,,
cowidev.vax.incremental.antigua_barbuda,4.27,True,2022-07-06T07:01:20,,
cowidev.vax.incremental.aruba,1.15,True,2022-07-06T07:01:20,,
cowidev.vax.incremental.azerbaijan,6.82,True,2022-07-06T07:01:26,,
cowidev.vax.incremental.bahrain,0.91,True,2022-07-06T07:01:21,,
cowidev.vax.incremental.bangladesh,13.24,True,2022-07-06T07:01:34,,
cowidev.vax.incremental.barbados,2.29,True,2022-07-06T07:01:23,,
cowidev.vax.incremental.brazil,0.05,True,2022-07-06T07:01:23,,
cowidev.vax.incremental.bulgaria,0.88,True,2022-07-06T07:01:24,,
cowidev.vax.incremental.china,84.53,True,2022-07-06T07:02:48,,
cowidev.vax.incremental.costa_rica,,,2022-07-06T07:01:24,,
cowidev.vax.incremental.croatia,0.12,True,2022-07-06T07:01:24,,
cowidev.vax.incremental.cuba,1.91,True,2022-07-06T07:01:26,,
cowidev.vax.incremental.curacao,0.35,True,2022-07-06T07:01:27,,
cowidev.vax.incremental.cyprus,0.64,True,2022-07-06T07:01:27,,
cowidev.vax.incremental.dominican_republic,6.09,True,2022-07-06T07:01:33,,
cowidev.vax.incremental.el_salvador,1.08,True,2022-07-06T07:01:28,,
cowidev.vax.incremental.faeroe_islands,0.34,True,2022-07-06T07:01:28,,
cowidev.vax.incremental.fiji,0.0,True,2022-07-06T07:01:28,,
cowidev.vax.incremental.finland,0.21,True,2022-07-06T07:01:28,,
cowidev.vax.incremental.gabon,,,2022-07-06T07:01:28,,
cowidev.vax.incremental.georgia,0.52,True,2022-07-06T07:01:29,,
cowidev.vax.incremental.greenland,0.49,True,2022-07-06T07:01:29,,
cowidev.vax.incremental.guatemala,,,2022-07-06T07:01:29,,
cowidev.vax.incremental.guernsey,0.09,True,2022-07-06T07:01:29,,
cowidev.vax.incremental.hungary,0.99,True,2022-07-06T07:01:30,,
cowidev.vax.incremental.iceland,0.22,True,2022-07-06T07:01:29,,
cowidev.vax.incremental.india,0.89,True,2022-07-06T07:01:30,,
cowidev.vax.incremental.iran,1.95,True,2022-07-06T07:01:32,,
cowidev.vax.incremental.isle_of_man,0.79,True,2022-07-06T07:01:31,,
cowidev.vax.incremental.jamaica,1.84,True,2022-07-06T07:01:33,,
cowidev.vax.incremental.kazakhstan,7.24,True,2022-07-06T07:01:39,,
cowidev.vax.incremental.kosovo,0.21,False,2022-07-06T07:03:29,"Traceback (most recent call last):
  File ""/mnt/owid_live_covid/covid-19-data/scripts/venv/lib/python3.9/site-packages/urllib3/connectionpool.py"", line 699, in urlopen
    httplib_response = self._make_request(
  File ""/mnt/owid_live_covid/covid-19-data/scripts/venv/lib/python3.9/site-packages/urllib3/connectionpool.py"", line 382, in _make_request
    self._validate_conn(conn)
  File ""/mnt/owid_live_covid/covid-19-data/scripts/venv/lib/python3.9/site-packages/urllib3/connectionpool.py"", line 1010, in _validate_conn
    conn.connect()
  File ""/mnt/owid_live_covid/covid-19-data/scripts/venv/lib/python3.9/site-packages/urllib3/connection.py"", line 416, in connect
    self.sock = ssl_wrap_socket(
  File ""/mnt/owid_live_covid/covid-19-data/scripts/venv/lib/python3.9/site-packages/urllib3/util/ssl_.py"", line 449, in ssl_wrap_socket
    ssl_sock = _ssl_wrap_socket_impl(
  File ""/mnt/owid_live_covid/covid-19-data/scripts/venv/lib/python3.9/site-packages/urllib3/util/ssl_.py"", line 493, in _ssl_wrap_socket_impl
    return ssl_context.wrap_socket(sock, server_hostname=server_hostname)
  File ""/home/owid/.pyenv/versions/3.9.6/lib/python3.9/ssl.py"", line 500, in wrap_socket
    return self.sslsocket_class._create(
  File ""/home/owid/.pyenv/versions/3.9.6/lib/python3.9/ssl.py"", line 1040, in _create
    self.do_handshake()
  File ""/home/owid/.pyenv/versions/3.9.6/lib/python3.9/ssl.py"", line 1309, in do_handshake
    self._sslobj.do_handshake()
ssl.SSLCertVerificationError: [SSL: CERTIFICATE_VERIFY_FAILED] certificate verify failed: unable to get local issuer certificate (_ssl.c:1129)

During handling of the above exception, another exception occurred:

Traceback (most recent call last):
  File ""/mnt/owid_live_covid/covid-19-data/scripts/venv/lib/python3.9/site-packages/requests/adapters.py"", line 440, in send
    resp = conn.urlopen(
  File ""/mnt/owid_live_covid/covid-19-data/scripts/venv/lib/python3.9/site-packages/urllib3/connectionpool.py"", line 755, in urlopen
    retries = retries.increment(
  File ""/mnt/owid_live_covid/covid-19-data/scripts/venv/lib/python3.9/site-packages/urllib3/util/retry.py"", line 574, in increment
    raise MaxRetryError(_pool, url, error or ResponseError(cause))
urllib3.exceptions.MaxRetryError: HTTPSConnectionPool(host='msh.rks-gov.net', port=443): Max retries exceeded with url: /sq/statistikat-covid-19/ (Caused by SSLError(SSLCertVerificationError(1, '[SSL: CERTIFICATE_VERIFY_FAILED] certificate verify failed: unable to get local issuer certificate (_ssl.c:1129)')))

During handling of the above exception, another exception occurred:

Traceback (most recent call last):
  File ""/mnt/owid_live_covid/covid-19-data/scripts/src/cowidev/cmd/commons/get.py"", line 47, in run
    module.main()
  File ""/mnt/owid_live_covid/covid-19-data/scripts/src/cowidev/vax/incremental/kosovo.py"", line 82, in main
    Kosovo().export()
  File ""/mnt/owid_live_covid/covid-19-data/scripts/src/cowidev/vax/incremental/kosovo.py"", line 77, in export
    df = self.read().pipe(self.pipeline)
  File ""/mnt/owid_live_covid/covid-19-data/scripts/src/cowidev/vax/incremental/kosovo.py"", line 22, in read
    soup = get_soup(self.source_url)
  File ""/mnt/owid_live_covid/covid-19-data/scripts/src/cowidev/utils/web/scraping.py"", line 83, in get_soup
    response = get_response(source, request_method, use_proxy, **kwargs)
  File ""/mnt/owid_live_covid/covid-19-data/scripts/src/cowidev/utils/web/scraping.py"", line 49, in get_response
    raise err
  File ""/mnt/owid_live_covid/covid-19-data/scripts/src/cowidev/utils/web/scraping.py"", line 43, in get_response
    response = requests.get(source, **kwargs)
  File ""/mnt/owid_live_covid/covid-19-data/scripts/venv/lib/python3.9/site-packages/requests/api.py"", line 75, in get
    return request('get', url, params=params, **kwargs)
  File ""/mnt/owid_live_covid/covid-19-data/scripts/venv/lib/python3.9/site-packages/requests/api.py"", line 61, in request
    return session.request(method=method, url=url, **kwargs)
  File ""/mnt/owid_live_covid/covid-19-data/scripts/venv/lib/python3.9/site-packages/requests/sessions.py"", line 529, in request
    resp = self.send(prep, **send_kwargs)
  File ""/mnt/owid_live_covid/covid-19-data/scripts/venv/lib/python3.9/site-packages/requests/sessions.py"", line 645, in send
    r = adapter.send(request, **kwargs)
  File ""/mnt/owid_live_covid/covid-19-data/scripts/venv/lib/python3.9/site-packages/requests/adapters.py"", line 517, in send
    raise SSLError(e, request=request)
requests.exceptions.SSLError: HTTPSConnectionPool(host='msh.rks-gov.net', port=443): Max retries exceeded with url: /sq/statistikat-covid-19/ (Caused by SSLError(SSLCertVerificationError(1, '[SSL: CERTIFICATE_VERIFY_FAILED] certificate verify failed: unable to get local issuer certificate (_ssl.c:1129)')))
","HTTPSConnectionPool(host='msh.rks-gov.net', port=443): Max retries exceeded with url: /sq/statistikat-covid-19/ (Caused by SSLError(SSLCertVerificationError(1, '[SSL: CERTIFICATE_VERIFY_FAILED] certificate verify failed: unable to get local issuer certificate (_ssl.c:1129)')))"
cowidev.vax.incremental.kyrgyzstan,0.94,True,2022-07-06T07:01:34,,
cowidev.vax.incremental.laos,2.15,True,2022-07-06T07:01:35,,
cowidev.vax.incremental.macao,25.99,True,2022-07-06T07:02:00,,
cowidev.vax.incremental.moldova,0.87,True,2022-07-06T07:01:34,,
cowidev.vax.incremental.monaco,38.83,True,2022-07-06T07:02:13,,
cowidev.vax.incremental.mongolia,0.94,True,2022-07-06T07:01:36,,
cowidev.vax.incremental.montenegro,0.55,True,2022-07-06T07:01:37,,
cowidev.vax.incremental.morocco,,,2022-07-06T07:01:37,,
cowidev.vax.incremental.myanmar,,,2022-07-06T07:01:37,,
cowidev.vax.incremental.nepal,48.38,False,2022-07-06T07:04:17,"Traceback (most recent call last):
  File ""/mnt/owid_live_covid/covid-19-data/scripts/src/cowidev/cmd/commons/get.py"", line 47, in run
    module.main()
  File ""/mnt/owid_live_covid/covid-19-data/scripts/src/cowidev/vax/incremental/nepal.py"", line 173, in main
    Nepal().export()
  File ""/mnt/owid_live_covid/covid-19-data/scripts/src/cowidev/vax/incremental/nepal.py"", line 155, in export
    df_main, df_manufacturer = self.read()
  File ""/mnt/owid_live_covid/covid-19-data/scripts/src/cowidev/vax/incremental/nepal.py"", line 29, in read
    df_main, df_manufacturer = self._parse_data(links)
  File ""/mnt/owid_live_covid/covid-19-data/scripts/src/cowidev/vax/incremental/nepal.py"", line 38, in _parse_data
    df = self._parse_pdf_table()
  File ""/mnt/owid_live_covid/covid-19-data/scripts/src/cowidev/vax/incremental/nepal.py"", line 49, in _parse_pdf_table
    check_known_columns(
  File ""/mnt/owid_live_covid/covid-19-data/scripts/src/cowidev/utils/utils.py"", line 164, in check_known_columns
    raise Exception(f""Unknown column(s) found: {unknown_cols}"")
Exception: Unknown column(s) found: {'Unnamed: 6'}
",Unknown column(s) found: {'Unnamed: 6'}
cowidev.vax.incremental.north_macedonia,,,2022-07-06T07:01:39,,
cowidev.vax.incremental.northern_cyprus,0.5,True,2022-07-06T07:01:40,,
cowidev.vax.incremental.paho,49.5,True,2022-07-06T07:02:29,,
cowidev.vax.incremental.pakistan,1.58,True,2022-07-06T07:02:01,,
cowidev.vax.incremental.philippines,,,2022-07-06T07:02:01,,
cowidev.vax.incremental.poland,0.13,True,2022-07-06T07:02:01,,
cowidev.vax.incremental.qatar,,,2022-07-06T07:02:01,,
cowidev.vax.incremental.russia,2.58,False,2022-07-06T07:04:20,"Traceback (most recent call last):
  File ""/mnt/owid_live_covid/covid-19-data/scripts/src/cowidev/cmd/commons/get.py"", line 47, in run
    module.main()
  File ""/mnt/owid_live_covid/covid-19-data/scripts/src/cowidev/vax/incremental/russia.py"", line 64, in main
    data = read(source).pipe(pipeline)
  File ""/mnt/owid_live_covid/covid-19-data/scripts/src/cowidev/vax/incremental/russia.py"", line 11, in read
    soup = get_soup(source)
  File ""/mnt/owid_live_covid/covid-19-data/scripts/src/cowidev/utils/web/scraping.py"", line 83, in get_soup
    response = get_response(source, request_method, use_proxy, **kwargs)
  File ""/mnt/owid_live_covid/covid-19-data/scripts/src/cowidev/utils/web/scraping.py"", line 52, in get_response
    raise ValueError(
ValueError: Source https://gogov.ru/articles/covid-v-stats not reached! Error code 502 Bad Gateway
",Source https://gogov.ru/articles/covid-v-stats not reached! Error code 502 Bad Gateway
cowidev.vax.incremental.saint_lucia,,,2022-07-06T07:02:02,,
cowidev.vax.incremental.serbia,25.83,True,2022-07-06T07:02:28,,
cowidev.vax.incremental.south_africa,7.53,True,2022-07-06T07:02:21,,
cowidev.vax.incremental.spain,3.56,True,2022-07-06T07:02:24,,
cowidev.vax.incremental.sri_lanka,,,2022-07-06T07:02:22,,
cowidev.vax.incremental.suriname,13.94,True,2022-07-06T07:02:36,,
cowidev.vax.incremental.taiwan,6.54,True,2022-07-06T07:02:31,,
cowidev.vax.incremental.thailand,1.6,True,2022-07-06T07:02:30,,
cowidev.vax.incremental.turkey,0.65,True,2022-07-06T07:02:30,,
cowidev.vax.incremental.united_arab_emirates,,,2022-07-06T07:02:30,,
cowidev.vax.incremental.vietnam,3.42,False,2022-07-06T07:04:23,"Traceback (most recent call last):
  File ""/mnt/owid_live_covid/covid-19-data/scripts/src/cowidev/cmd/commons/get.py"", line 47, in run
    module.main()
  File ""/mnt/owid_live_covid/covid-19-data/scripts/src/cowidev/vax/incremental/vietnam.py"", line 137, in main
    Vietnam().export()
  File ""/mnt/owid_live_covid/covid-19-data/scripts/src/cowidev/vax/incremental/vietnam.py"", line 123, in export
    data = self.read().pipe(self.pipeline)
  File ""/mnt/owid_live_covid/covid-19-data/scripts/src/cowidev/vax/incremental/vietnam.py"", line 47, in read
    data = self._parse_data(soup)
  File ""/mnt/owid_live_covid/covid-19-data/scripts/src/cowidev/vax/incremental/vietnam.py"", line 60, in _parse_data
    metrics = self._parse_metrics(text)
  File ""/mnt/owid_live_covid/covid-19-data/scripts/src/cowidev/vax/incremental/vietnam.py"", line 89, in _parse_metrics
    all = clean_count(re.search(self.regex[""metrics""][""all""], text).group(2))
AttributeError: 'NoneType' object has no attribute 'group'
",'NoneType' object has no attribute 'group'
cowidev.vax.incremental.who,2.96,True,2022-07-06T07:02:33,,
cowidev.vax.incremental.zambia,0.44,True,2022-07-06T07:02:31,,
