module,execution_time (sec),success,timestamp,error,error_short
cowidev.vax.batch.argentina,3.98,True,2022-09-14T07:00:15,,
cowidev.vax.batch.australia,1.96,True,2022-09-14T07:00:13,,
cowidev.vax.batch.austria,2.72,True,2022-09-14T07:00:13,,
cowidev.vax.batch.belgium,2.28,True,2022-09-14T07:00:13,,
cowidev.vax.batch.bolivia,2.33,True,2022-09-14T07:00:13,,
cowidev.vax.batch.canada,5.5,True,2022-09-14T07:00:18,,
cowidev.vax.batch.chile,1.85,True,2022-09-14T07:00:15,,
cowidev.vax.batch.czechia,2.17,False,2022-09-14T07:03:26,"Traceback (most recent call last):
  File ""/mnt/owid_live_covid/covid-19-data/scripts/src/cowidev/cmd/commons/get.py"", line 47, in run
    module.main()
  File ""/mnt/owid_live_covid/covid-19-data/scripts/src/cowidev/vax/batch/czechia.py"", line 184, in main
    Czechia().export()
  File ""/mnt/owid_live_covid/covid-19-data/scripts/src/cowidev/vax/batch/czechia.py"", line 169, in export
    base = read(self.source_url).pipe(base_pipeline)
  File ""/mnt/owid_live_covid/covid-19-data/scripts/venv/lib/python3.9/site-packages/pandas/core/generic.py"", line 5430, in pipe
    return com.pipe(self, func, *args, **kwargs)
  File ""/mnt/owid_live_covid/covid-19-data/scripts/venv/lib/python3.9/site-packages/pandas/core/common.py"", line 471, in pipe
    return func(obj, *args, **kwargs)
  File ""/mnt/owid_live_covid/covid-19-data/scripts/src/cowidev/vax/batch/czechia.py"", line 67, in base_pipeline
    return df.pipe(check_vaccine_names).pipe(translate_vaccine_names)
  File ""/mnt/owid_live_covid/covid-19-data/scripts/venv/lib/python3.9/site-packages/pandas/core/generic.py"", line 5430, in pipe
    return com.pipe(self, func, *args, **kwargs)
  File ""/mnt/owid_live_covid/covid-19-data/scripts/venv/lib/python3.9/site-packages/pandas/core/common.py"", line 471, in pipe
    return func(obj, *args, **kwargs)
  File ""/mnt/owid_live_covid/covid-19-data/scripts/src/cowidev/vax/batch/czechia.py"", line 46, in check_vaccine_names
    raise ValueError(""Found unknown vaccines: {}"".format(unknown_vaccines))
ValueError: Found unknown vaccines: {'Comirnaty Original/Omicron BA.4/BA.5', 'Spikevax bivalent Original/Omicron BA.1'}
","Found unknown vaccines: {'Comirnaty Original/Omicron BA.4/BA.5', 'Spikevax bivalent Original/Omicron BA.1'}"
cowidev.vax.batch.denmark,1.35,False,2022-09-14T07:03:28,"Traceback (most recent call last):
  File ""/mnt/owid_live_covid/covid-19-data/scripts/src/cowidev/cmd/commons/get.py"", line 47, in run
    module.main()
  File ""/mnt/owid_live_covid/covid-19-data/scripts/src/cowidev/vax/batch/denmark.py"", line 243, in main
    Denmark().export()
  File ""/mnt/owid_live_covid/covid-19-data/scripts/src/cowidev/vax/batch/denmark.py"", line 224, in export
    df = self.read(index).pipe(self.pipeline, df_current)
  File ""/mnt/owid_live_covid/covid-19-data/scripts/src/cowidev/vax/batch/denmark.py"", line 46, in read
    df = self._load_data(tf)
  File ""/mnt/owid_live_covid/covid-19-data/scripts/src/cowidev/vax/batch/denmark.py"", line 58, in _load_data
    df_ss = pd.DataFrame([self._read_single_shots_daily(path)])
  File ""/mnt/owid_live_covid/covid-19-data/scripts/src/cowidev/vax/batch/denmark.py"", line 122, in _read_single_shots_daily
    raise ValueError(f""Unknown vaccine(s) {vaccines_wrong}"")
ValueError: Unknown vaccine(s) {'Pfizer/Comirnaty Original/Omikron BA1'}
",Unknown vaccine(s) {'Pfizer/Comirnaty Original/Omikron BA1'}
cowidev.vax.batch.ecdc,126.9,True,2022-09-14T07:02:21,,
cowidev.vax.batch.ecuador,1.22,True,2022-09-14T07:00:16,,
cowidev.vax.batch.estonia,0.63,True,2022-09-14T07:00:17,,
cowidev.vax.batch.france,0.43,True,2022-09-14T07:00:17,,
cowidev.vax.batch.germany,1.79,True,2022-09-14T07:00:18,,
cowidev.vax.batch.greece,2.61,True,2022-09-14T07:00:19,,
cowidev.vax.batch.hong_kong,11.28,True,2022-09-14T07:00:29,,
cowidev.vax.batch.indonesia,,,2022-09-14T07:00:18,,
cowidev.vax.batch.ireland,0.88,True,2022-09-14T07:00:19,,
cowidev.vax.batch.israel,10.48,True,2022-09-14T07:00:29,,
cowidev.vax.batch.italy,9.84,True,2022-09-14T07:00:29,,
cowidev.vax.batch.japan,1.21,False,2022-09-14T07:03:29,"Traceback (most recent call last):
  File ""/mnt/owid_live_covid/covid-19-data/scripts/src/cowidev/cmd/commons/get.py"", line 47, in run
    module.main()
  File ""/mnt/owid_live_covid/covid-19-data/scripts/src/cowidev/vax/batch/japan.py"", line 236, in main
    Japan().export()
  File ""/mnt/owid_live_covid/covid-19-data/scripts/src/cowidev/vax/batch/japan.py"", line 220, in export
    df = self.read().pipe(self.pipeline_base)
  File ""/mnt/owid_live_covid/covid-19-data/scripts/src/cowidev/vax/batch/japan.py"", line 156, in read
    df_latest = self.read_latest().pipe(self.pipe_latest)
  File ""/mnt/owid_live_covid/covid-19-data/scripts/src/cowidev/vax/batch/japan.py"", line 88, in read_latest
    dfs.append(self._read_xlsx(self.source_url, self.sheets, self.metrics))
  File ""/mnt/owid_live_covid/covid-19-data/scripts/src/cowidev/vax/batch/japan.py"", line 97, in _read_xlsx
    xlsx = pd.ExcelFile(url)
  File ""/mnt/owid_live_covid/covid-19-data/scripts/venv/lib/python3.9/site-packages/pandas/io/excel/_base.py"", line 1191, in __init__
    ext = inspect_excel_format(
  File ""/mnt/owid_live_covid/covid-19-data/scripts/venv/lib/python3.9/site-packages/pandas/io/excel/_base.py"", line 1070, in inspect_excel_format
    with get_handle(
  File ""/mnt/owid_live_covid/covid-19-data/scripts/venv/lib/python3.9/site-packages/pandas/io/common.py"", line 609, in get_handle
    ioargs = _get_filepath_or_buffer(
  File ""/mnt/owid_live_covid/covid-19-data/scripts/venv/lib/python3.9/site-packages/pandas/io/common.py"", line 312, in _get_filepath_or_buffer
    with urlopen(req_info) as req:
  File ""/mnt/owid_live_covid/covid-19-data/scripts/venv/lib/python3.9/site-packages/pandas/io/common.py"", line 212, in urlopen
    return urllib.request.urlopen(*args, **kwargs)
  File ""/home/owid/.pyenv/versions/3.9.6/lib/python3.9/urllib/request.py"", line 214, in urlopen
    return opener.open(url, data, timeout)
  File ""/home/owid/.pyenv/versions/3.9.6/lib/python3.9/urllib/request.py"", line 523, in open
    response = meth(req, response)
  File ""/home/owid/.pyenv/versions/3.9.6/lib/python3.9/urllib/request.py"", line 632, in http_response
    response = self.parent.error(
  File ""/home/owid/.pyenv/versions/3.9.6/lib/python3.9/urllib/request.py"", line 561, in error
    return self._call_chain(*args)
  File ""/home/owid/.pyenv/versions/3.9.6/lib/python3.9/urllib/request.py"", line 494, in _call_chain
    result = func(*args)
  File ""/home/owid/.pyenv/versions/3.9.6/lib/python3.9/urllib/request.py"", line 641, in http_error_default
    raise HTTPError(req.full_url, code, msg, hdrs, fp)
urllib.error.HTTPError: HTTP Error 404: Not Found
",HTTP Error 404: Not Found
cowidev.vax.batch.jersey,0.7,True,2022-09-14T07:00:30,,
cowidev.vax.batch.latvia,18.89,True,2022-09-14T07:00:48,,
cowidev.vax.batch.lithuania,1.89,True,2022-09-14T07:00:31,,
cowidev.vax.batch.luxembourg,2.36,True,2022-09-14T07:00:32,,
cowidev.vax.batch.malaysia,0.65,True,2022-09-14T07:00:30,,
cowidev.vax.batch.malta,1.06,True,2022-09-14T07:00:31,,
cowidev.vax.batch.netherlands,,,2022-09-14T07:00:31,,
cowidev.vax.batch.new_zealand,13.73,True,2022-09-14T07:00:45,,
cowidev.vax.batch.norway,0.35,True,2022-09-14T07:00:32,,
cowidev.vax.batch.peru,5.06,True,2022-09-14T07:00:37,,
cowidev.vax.batch.portugal,,,2022-09-14T07:00:32,,
cowidev.vax.batch.romania,15.28,True,2022-09-14T07:00:47,,
cowidev.vax.batch.saudi_arabia,10.58,True,2022-09-14T07:00:47,,
cowidev.vax.batch.singapore,2.17,True,2022-09-14T07:00:47,,
cowidev.vax.batch.slovakia,62.49,True,2022-09-14T07:01:50,,
cowidev.vax.batch.slovenia,0.5,True,2022-09-14T07:00:48,,
cowidev.vax.batch.south_korea,71.9,True,2022-09-14T07:01:59,,
cowidev.vax.batch.spc,18.05,True,2022-09-14T07:01:06,,
cowidev.vax.batch.sweden,12.14,True,2022-09-14T07:01:00,,
cowidev.vax.batch.switzerland,63.18,True,2022-09-14T07:02:03,,
cowidev.vax.batch.trinidad_and_tobago,1.83,True,2022-09-14T07:01:08,,
cowidev.vax.batch.ukraine,,,2022-09-14T07:01:08,,
cowidev.vax.batch.united_kingdom,10.94,True,2022-09-14T07:01:18,,
cowidev.vax.batch.united_states,67.29,True,2022-09-14T07:02:26,,
cowidev.vax.batch.uruguay,3.77,True,2022-09-14T07:01:53,,
cowidev.vax.batch.zimbabwe,1.52,True,2022-09-14T07:01:55,,
cowidev.vax.incremental.africacdc,,,2022-09-14T07:01:55,,
cowidev.vax.incremental.antigua_barbuda,4.2,True,2022-09-14T07:01:59,,
cowidev.vax.incremental.aruba,1.51,True,2022-09-14T07:02:01,,
cowidev.vax.incremental.azerbaijan,,,2022-09-14T07:01:59,,
cowidev.vax.incremental.bahrain,2.11,True,2022-09-14T07:02:01,,
cowidev.vax.incremental.bangladesh,22.7,True,2022-09-14T07:02:23,,
cowidev.vax.incremental.barbados,9.88,True,2022-09-14T07:02:11,,
cowidev.vax.incremental.brazil,0.51,True,2022-09-14T07:02:04,,
cowidev.vax.incremental.bulgaria,6.44,True,2022-09-14T07:02:10,,
cowidev.vax.incremental.china,34.59,True,2022-09-14T07:02:45,,
cowidev.vax.incremental.costa_rica,,,2022-09-14T07:02:11,,
cowidev.vax.incremental.croatia,0.38,True,2022-09-14T07:02:12,,
cowidev.vax.incremental.cuba,3.44,True,2022-09-14T07:02:15,,
cowidev.vax.incremental.curacao,0.46,True,2022-09-14T07:02:15,,
cowidev.vax.incremental.cyprus,1.42,True,2022-09-14T07:02:17,,
cowidev.vax.incremental.dominican_republic,6.21,True,2022-09-14T07:02:23,,
cowidev.vax.incremental.el_salvador,1.02,True,2022-09-14T07:02:23,,
cowidev.vax.incremental.faeroe_islands,0.53,True,2022-09-14T07:02:23,,
cowidev.vax.incremental.fiji,0.0,True,2022-09-14T07:02:23,,
cowidev.vax.incremental.finland,0.24,True,2022-09-14T07:02:23,,
cowidev.vax.incremental.gabon,,,2022-09-14T07:02:23,,
cowidev.vax.incremental.georgia,0.69,True,2022-09-14T07:02:24,,
cowidev.vax.incremental.greenland,0.97,True,2022-09-14T07:02:24,,
cowidev.vax.incremental.guatemala,,,2022-09-14T07:02:23,,
cowidev.vax.incremental.guernsey,0.23,True,2022-09-14T07:02:24,,
cowidev.vax.incremental.hungary,1.72,True,2022-09-14T07:02:25,,
cowidev.vax.incremental.iceland,0.23,True,2022-09-14T07:02:24,,
cowidev.vax.incremental.india,0.89,True,2022-09-14T07:02:25,,
cowidev.vax.incremental.iran,,,2022-09-14T07:02:24,,
cowidev.vax.incremental.isle_of_man,0.89,True,2022-09-14T07:02:25,,
cowidev.vax.incremental.jamaica,1.96,True,2022-09-14T07:02:27,,
cowidev.vax.incremental.kazakhstan,7.58,True,2022-09-14T07:02:33,,
cowidev.vax.incremental.kosovo,6.25,False,2022-09-14T07:03:35,"Traceback (most recent call last):
  File ""/mnt/owid_live_covid/covid-19-data/scripts/src/cowidev/cmd/commons/get.py"", line 47, in run
    module.main()
  File ""/mnt/owid_live_covid/covid-19-data/scripts/src/cowidev/vax/incremental/kosovo.py"", line 82, in main
    Kosovo().export()
  File ""/mnt/owid_live_covid/covid-19-data/scripts/src/cowidev/vax/incremental/kosovo.py"", line 77, in export
    df = self.read().pipe(self.pipeline)
  File ""/mnt/owid_live_covid/covid-19-data/scripts/src/cowidev/vax/incremental/kosovo.py"", line 23, in read
    df = self._parse_data(soup)
  File ""/mnt/owid_live_covid/covid-19-data/scripts/src/cowidev/vax/incremental/kosovo.py"", line 32, in _parse_data
    soup = get_soup(link, verify=False)
  File ""/mnt/owid_live_covid/covid-19-data/scripts/src/cowidev/utils/web/scraping.py"", line 83, in get_soup
    response = get_response(source, request_method, use_proxy, **kwargs)
  File ""/mnt/owid_live_covid/covid-19-data/scripts/src/cowidev/utils/web/scraping.py"", line 52, in get_response
    raise ValueError(
ValueError: Source https://msh.rks-gov.net/10.230.0.57+9000/coviddashboard.html not reached! Error code 404 Not Found
",Source https://msh.rks-gov.net/10.230.0.57+9000/coviddashboard.html not reached! Error code 404 Not Found
cowidev.vax.incremental.kyrgyzstan,1.11,True,2022-09-14T07:02:27,,
cowidev.vax.incremental.laos,2.35,True,2022-09-14T07:02:29,,
cowidev.vax.incremental.macao,25.08,False,2022-09-14T07:04:00,"Traceback (most recent call last):
  File ""/mnt/owid_live_covid/covid-19-data/scripts/src/cowidev/cmd/commons/get.py"", line 47, in run
    module.main()
  File ""/mnt/owid_live_covid/covid-19-data/scripts/src/cowidev/vax/incremental/macao.py"", line 86, in main
    Macao().export()
  File ""/mnt/owid_live_covid/covid-19-data/scripts/src/cowidev/vax/incremental/macao.py"", line 72, in export
    data = self.read()
  File ""/mnt/owid_live_covid/covid-19-data/scripts/src/cowidev/vax/incremental/macao.py"", line 20, in read
    elem = driver.find_element_by_partial_link_text(""Daily Bulletin on COVID-19"")
  File ""/mnt/owid_live_covid/covid-19-data/scripts/venv/lib/python3.9/site-packages/selenium/webdriver/remote/webdriver.py"", line 462, in find_element_by_partial_link_text
    return self.find_element(by=By.PARTIAL_LINK_TEXT, value=link_text)
  File ""/mnt/owid_live_covid/covid-19-data/scripts/venv/lib/python3.9/site-packages/selenium/webdriver/remote/webdriver.py"", line 976, in find_element
    return self.execute(Command.FIND_ELEMENT, {
  File ""/mnt/owid_live_covid/covid-19-data/scripts/venv/lib/python3.9/site-packages/selenium/webdriver/remote/webdriver.py"", line 321, in execute
    self.error_handler.check_response(response)
  File ""/mnt/owid_live_covid/covid-19-data/scripts/venv/lib/python3.9/site-packages/selenium/webdriver/remote/errorhandler.py"", line 242, in check_response
    raise exception_class(message, screen, stacktrace)
selenium.common.exceptions.NoSuchElementException: Message: no such element: Unable to locate element: {""method"":""partial link text"",""selector"":""Daily Bulletin on COVID-19""}
  (Session info: headless chrome=104.0.5112.101)

","Message: no such element: Unable to locate element: {""method"":""partial link text"",""selector"":""Daily Bulletin on COVID-19""}
  (Session info: headless chrome=104.0.5112.101)
"
cowidev.vax.incremental.moldova,40.07,False,2022-09-14T07:04:40,"Traceback (most recent call last):
  File ""/mnt/owid_live_covid/covid-19-data/scripts/venv/lib/python3.9/site-packages/urllib3/connection.py"", line 174, in _new_conn
    conn = connection.create_connection(
  File ""/mnt/owid_live_covid/covid-19-data/scripts/venv/lib/python3.9/site-packages/urllib3/util/connection.py"", line 96, in create_connection
    raise err
  File ""/mnt/owid_live_covid/covid-19-data/scripts/venv/lib/python3.9/site-packages/urllib3/util/connection.py"", line 86, in create_connection
    sock.connect(sa)
socket.timeout: timed out

During handling of the above exception, another exception occurred:

Traceback (most recent call last):
  File ""/mnt/owid_live_covid/covid-19-data/scripts/venv/lib/python3.9/site-packages/urllib3/connectionpool.py"", line 699, in urlopen
    httplib_response = self._make_request(
  File ""/mnt/owid_live_covid/covid-19-data/scripts/venv/lib/python3.9/site-packages/urllib3/connectionpool.py"", line 382, in _make_request
    self._validate_conn(conn)
  File ""/mnt/owid_live_covid/covid-19-data/scripts/venv/lib/python3.9/site-packages/urllib3/connectionpool.py"", line 1010, in _validate_conn
    conn.connect()
  File ""/mnt/owid_live_covid/covid-19-data/scripts/venv/lib/python3.9/site-packages/urllib3/connection.py"", line 358, in connect
    conn = self._new_conn()
  File ""/mnt/owid_live_covid/covid-19-data/scripts/venv/lib/python3.9/site-packages/urllib3/connection.py"", line 179, in _new_conn
    raise ConnectTimeoutError(
urllib3.exceptions.ConnectTimeoutError: (<urllib3.connection.HTTPSConnection object at 0x7f725ce4a2e0>, 'Connection to vaccinare.gov.md timed out. (connect timeout=20)')

During handling of the above exception, another exception occurred:

Traceback (most recent call last):
  File ""/mnt/owid_live_covid/covid-19-data/scripts/venv/lib/python3.9/site-packages/requests/adapters.py"", line 440, in send
    resp = conn.urlopen(
  File ""/mnt/owid_live_covid/covid-19-data/scripts/venv/lib/python3.9/site-packages/urllib3/connectionpool.py"", line 755, in urlopen
    retries = retries.increment(
  File ""/mnt/owid_live_covid/covid-19-data/scripts/venv/lib/python3.9/site-packages/urllib3/util/retry.py"", line 574, in increment
    raise MaxRetryError(_pool, url, error or ResponseError(cause))
urllib3.exceptions.MaxRetryError: HTTPSConnectionPool(host='vaccinare.gov.md', port=443): Max retries exceeded with url: / (Caused by ConnectTimeoutError(<urllib3.connection.HTTPSConnection object at 0x7f725ce4a2e0>, 'Connection to vaccinare.gov.md timed out. (connect timeout=20)'))

During handling of the above exception, another exception occurred:

Traceback (most recent call last):
  File ""/mnt/owid_live_covid/covid-19-data/scripts/src/cowidev/cmd/commons/get.py"", line 47, in run
    module.main()
  File ""/mnt/owid_live_covid/covid-19-data/scripts/src/cowidev/vax/incremental/moldova.py"", line 59, in main
    Moldova().export()
  File ""/mnt/owid_live_covid/covid-19-data/scripts/src/cowidev/vax/incremental/moldova.py"", line 54, in export
    df = self.read().pipe(self.pipeline)
  File ""/mnt/owid_live_covid/covid-19-data/scripts/src/cowidev/vax/incremental/moldova.py"", line 17, in read
    soup = get_soup(self.source_url)
  File ""/mnt/owid_live_covid/covid-19-data/scripts/src/cowidev/utils/web/scraping.py"", line 83, in get_soup
    response = get_response(source, request_method, use_proxy, **kwargs)
  File ""/mnt/owid_live_covid/covid-19-data/scripts/src/cowidev/utils/web/scraping.py"", line 49, in get_response
    raise err
  File ""/mnt/owid_live_covid/covid-19-data/scripts/src/cowidev/utils/web/scraping.py"", line 43, in get_response
    response = requests.get(source, **kwargs)
  File ""/mnt/owid_live_covid/covid-19-data/scripts/venv/lib/python3.9/site-packages/requests/api.py"", line 75, in get
    return request('get', url, params=params, **kwargs)
  File ""/mnt/owid_live_covid/covid-19-data/scripts/venv/lib/python3.9/site-packages/requests/api.py"", line 61, in request
    return session.request(method=method, url=url, **kwargs)
  File ""/mnt/owid_live_covid/covid-19-data/scripts/venv/lib/python3.9/site-packages/requests/sessions.py"", line 529, in request
    resp = self.send(prep, **send_kwargs)
  File ""/mnt/owid_live_covid/covid-19-data/scripts/venv/lib/python3.9/site-packages/requests/sessions.py"", line 645, in send
    r = adapter.send(request, **kwargs)
  File ""/mnt/owid_live_covid/covid-19-data/scripts/venv/lib/python3.9/site-packages/requests/adapters.py"", line 507, in send
    raise ConnectTimeout(e, request=request)
requests.exceptions.ConnectTimeout: HTTPSConnectionPool(host='vaccinare.gov.md', port=443): Max retries exceeded with url: / (Caused by ConnectTimeoutError(<urllib3.connection.HTTPSConnection object at 0x7f725ce4a2e0>, 'Connection to vaccinare.gov.md timed out. (connect timeout=20)'))
","HTTPSConnectionPool(host='vaccinare.gov.md', port=443): Max retries exceeded with url: / (Caused by ConnectTimeoutError(<urllib3.connection.HTTPSConnection object at 0x7f725ce4a2e0>, 'Connection to vaccinare.gov.md timed out. (connect timeout=20)'))"
cowidev.vax.incremental.monaco,33.97,True,2022-09-14T07:03:06,,
cowidev.vax.incremental.mongolia,0.63,True,2022-09-14T07:02:33,,
cowidev.vax.incremental.montenegro,0.1,True,2022-09-14T07:02:33,,
cowidev.vax.incremental.morocco,,,2022-09-14T07:02:33,,
cowidev.vax.incremental.myanmar,,,2022-09-14T07:02:33,,
cowidev.vax.incremental.nepal,,,2022-09-14T07:02:33,,
cowidev.vax.incremental.north_macedonia,,,2022-09-14T07:02:33,,
cowidev.vax.incremental.northern_cyprus,0.8,True,2022-09-14T07:02:34,,
cowidev.vax.incremental.paho,49.95,True,2022-09-14T07:03:24,,
cowidev.vax.incremental.pakistan,1.67,True,2022-09-14T07:02:46,,
cowidev.vax.incremental.philippines,,,2022-09-14T07:02:46,,
cowidev.vax.incremental.poland,0.29,True,2022-09-14T07:02:47,,
cowidev.vax.incremental.qatar,,,2022-09-14T07:02:47,,
cowidev.vax.incremental.russia,0.45,False,2022-09-14T07:04:41,"Traceback (most recent call last):
  File ""/mnt/owid_live_covid/covid-19-data/scripts/src/cowidev/cmd/commons/get.py"", line 47, in run
    module.main()
  File ""/mnt/owid_live_covid/covid-19-data/scripts/src/cowidev/vax/incremental/russia.py"", line 80, in main
    Russia().export()
  File ""/mnt/owid_live_covid/covid-19-data/scripts/src/cowidev/vax/incremental/russia.py"", line 66, in export
    data = read(source).pipe(pipeline)
  File ""/mnt/owid_live_covid/covid-19-data/scripts/src/cowidev/vax/incremental/russia.py"", line 11, in read
    soup = get_soup(source)
  File ""/mnt/owid_live_covid/covid-19-data/scripts/src/cowidev/utils/web/scraping.py"", line 83, in get_soup
    response = get_response(source, request_method, use_proxy, **kwargs)
  File ""/mnt/owid_live_covid/covid-19-data/scripts/src/cowidev/utils/web/scraping.py"", line 52, in get_response
    raise ValueError(
ValueError: Source https://gogov.ru/articles/covid-v-stats not reached! Error code 502 Bad Gateway
",Source https://gogov.ru/articles/covid-v-stats not reached! Error code 502 Bad Gateway
cowidev.vax.incremental.saint_lucia,,,2022-09-14T07:02:47,,
cowidev.vax.incremental.serbia,6.94,True,2022-09-14T07:02:54,,
cowidev.vax.incremental.south_africa,6.59,True,2022-09-14T07:03:01,,
cowidev.vax.incremental.spain,4.13,True,2022-09-14T07:02:58,,
cowidev.vax.incremental.sri_lanka,,,2022-09-14T07:02:58,,
cowidev.vax.incremental.suriname,14.55,True,2022-09-14T07:03:13,,
cowidev.vax.incremental.taiwan,4.67,True,2022-09-14T07:03:05,,
cowidev.vax.incremental.thailand,4.32,True,2022-09-14T07:03:10,,
cowidev.vax.incremental.turkey,0.57,True,2022-09-14T07:03:06,,
cowidev.vax.incremental.united_arab_emirates,,,2022-09-14T07:03:06,,
cowidev.vax.incremental.vietnam,,,2022-09-14T07:03:06,,
cowidev.vax.incremental.who,4.13,True,2022-09-14T07:03:10,,
cowidev.vax.incremental.zambia,0.88,True,2022-09-14T07:03:10,,
