module,execution_time (sec),success,timestamp,error,error_short
cowidev.vax.batch.argentina,2.9,True,2022-07-02T07:00:11,,
cowidev.vax.batch.australia,2.17,True,2022-07-02T07:00:10,,
cowidev.vax.batch.austria,,,2022-07-02T07:00:08,,
cowidev.vax.batch.belgium,1.34,True,2022-07-02T07:00:09,,
cowidev.vax.batch.bolivia,1.62,True,2022-07-02T07:00:09,,
cowidev.vax.batch.canada,4.79,True,2022-07-02T07:00:13,,
cowidev.vax.batch.chile,0.91,True,2022-07-02T07:00:10,,
cowidev.vax.batch.czechia,3.31,True,2022-07-02T07:00:13,,
cowidev.vax.batch.denmark,3.24,True,2022-07-02T07:00:13,,
cowidev.vax.batch.ecdc,40.04,False,2022-07-02T07:03:09,"Traceback (most recent call last):
  File ""/mnt/owid_live_covid/covid-19-data/scripts/venv/lib/python3.9/site-packages/urllib3/connection.py"", line 174, in _new_conn
    conn = connection.create_connection(
  File ""/mnt/owid_live_covid/covid-19-data/scripts/venv/lib/python3.9/site-packages/urllib3/util/connection.py"", line 96, in create_connection
    raise err
  File ""/mnt/owid_live_covid/covid-19-data/scripts/venv/lib/python3.9/site-packages/urllib3/util/connection.py"", line 86, in create_connection
    sock.connect(sa)
socket.timeout: timed out

During handling of the above exception, another exception occurred:

Traceback (most recent call last):
  File ""/mnt/owid_live_covid/covid-19-data/scripts/venv/lib/python3.9/site-packages/urllib3/connectionpool.py"", line 699, in urlopen
    httplib_response = self._make_request(
  File ""/mnt/owid_live_covid/covid-19-data/scripts/venv/lib/python3.9/site-packages/urllib3/connectionpool.py"", line 382, in _make_request
    self._validate_conn(conn)
  File ""/mnt/owid_live_covid/covid-19-data/scripts/venv/lib/python3.9/site-packages/urllib3/connectionpool.py"", line 1010, in _validate_conn
    conn.connect()
  File ""/mnt/owid_live_covid/covid-19-data/scripts/venv/lib/python3.9/site-packages/urllib3/connection.py"", line 358, in connect
    conn = self._new_conn()
  File ""/mnt/owid_live_covid/covid-19-data/scripts/venv/lib/python3.9/site-packages/urllib3/connection.py"", line 179, in _new_conn
    raise ConnectTimeoutError(
urllib3.exceptions.ConnectTimeoutError: (<urllib3.connection.HTTPSConnection object at 0x7fb356584c10>, 'Connection to opendata.ecdc.europa.eu timed out. (connect timeout=20)')

During handling of the above exception, another exception occurred:

Traceback (most recent call last):
  File ""/mnt/owid_live_covid/covid-19-data/scripts/venv/lib/python3.9/site-packages/requests/adapters.py"", line 440, in send
    resp = conn.urlopen(
  File ""/mnt/owid_live_covid/covid-19-data/scripts/venv/lib/python3.9/site-packages/urllib3/connectionpool.py"", line 755, in urlopen
    retries = retries.increment(
  File ""/mnt/owid_live_covid/covid-19-data/scripts/venv/lib/python3.9/site-packages/urllib3/util/retry.py"", line 574, in increment
    raise MaxRetryError(_pool, url, error or ResponseError(cause))
urllib3.exceptions.MaxRetryError: HTTPSConnectionPool(host='opendata.ecdc.europa.eu', port=443): Max retries exceeded with url: /covid19/vaccine_tracker/csv/data.csv (Caused by ConnectTimeoutError(<urllib3.connection.HTTPSConnection object at 0x7fb356584c10>, 'Connection to opendata.ecdc.europa.eu timed out. (connect timeout=20)'))

During handling of the above exception, another exception occurred:

Traceback (most recent call last):
  File ""/mnt/owid_live_covid/covid-19-data/scripts/src/cowidev/cmd/commons/get.py"", line 47, in run
    module.main()
  File ""/mnt/owid_live_covid/covid-19-data/scripts/src/cowidev/vax/batch/ecdc.py"", line 499, in main
    ECDC().export()
  File ""/mnt/owid_live_covid/covid-19-data/scripts/src/cowidev/vax/batch/ecdc.py"", line 489, in export
    df = self.read().pipe(self.pipe_base)
  File ""/mnt/owid_live_covid/covid-19-data/scripts/src/cowidev/vax/batch/ecdc.py"", line 111, in read
    df = read_csv_from_url(self.source_url, timeout=20)
  File ""/mnt/owid_live_covid/covid-19-data/scripts/src/cowidev/utils/web/download.py"", line 39, in read_csv_from_url
    download_file_from_url(url, tmp.name, timeout=timeout, verify=verify, ciphers_low=ciphers_low)
  File ""/mnt/owid_live_covid/covid-19-data/scripts/src/cowidev/utils/web/download.py"", line 52, in download_file_from_url
    r = requests.get(url, stream=True, timeout=timeout, verify=verify)
  File ""/mnt/owid_live_covid/covid-19-data/scripts/venv/lib/python3.9/site-packages/requests/api.py"", line 75, in get
    return request('get', url, params=params, **kwargs)
  File ""/mnt/owid_live_covid/covid-19-data/scripts/venv/lib/python3.9/site-packages/requests/api.py"", line 61, in request
    return session.request(method=method, url=url, **kwargs)
  File ""/mnt/owid_live_covid/covid-19-data/scripts/venv/lib/python3.9/site-packages/requests/sessions.py"", line 529, in request
    resp = self.send(prep, **send_kwargs)
  File ""/mnt/owid_live_covid/covid-19-data/scripts/venv/lib/python3.9/site-packages/requests/sessions.py"", line 645, in send
    r = adapter.send(request, **kwargs)
  File ""/mnt/owid_live_covid/covid-19-data/scripts/venv/lib/python3.9/site-packages/requests/adapters.py"", line 507, in send
    raise ConnectTimeout(e, request=request)
requests.exceptions.ConnectTimeout: HTTPSConnectionPool(host='opendata.ecdc.europa.eu', port=443): Max retries exceeded with url: /covid19/vaccine_tracker/csv/data.csv (Caused by ConnectTimeoutError(<urllib3.connection.HTTPSConnection object at 0x7fb356584c10>, 'Connection to opendata.ecdc.europa.eu timed out. (connect timeout=20)'))
","HTTPSConnectionPool(host='opendata.ecdc.europa.eu', port=443): Max retries exceeded with url: /covid19/vaccine_tracker/csv/data.csv (Caused by ConnectTimeoutError(<urllib3.connection.HTTPSConnection object at 0x7fb356584c10>, 'Connection to opendata.ecdc.europa.eu timed out. (connect timeout=20)'))"
cowidev.vax.batch.ecuador,1.61,True,2022-07-02T07:00:12,,
cowidev.vax.batch.estonia,0.95,True,2022-07-02T07:00:13,,
cowidev.vax.batch.france,0.63,True,2022-07-02T07:00:13,,
cowidev.vax.batch.germany,1.56,True,2022-07-02T07:00:14,,
cowidev.vax.batch.greece,8.0,True,2022-07-02T07:00:21,,
cowidev.vax.batch.hong_kong,8.4,True,2022-07-02T07:00:22,,
cowidev.vax.batch.indonesia,,,2022-07-02T07:00:13,,
cowidev.vax.batch.ireland,0.44,True,2022-07-02T07:00:14,,
cowidev.vax.batch.israel,5.99,True,2022-07-02T07:00:20,,
cowidev.vax.batch.italy,7.16,True,2022-07-02T07:00:21,,
cowidev.vax.batch.japan,32.53,True,2022-07-02T07:00:52,,
cowidev.vax.batch.jersey,0.58,True,2022-07-02T07:00:22,,
cowidev.vax.batch.latvia,23.37,True,2022-07-02T07:00:45,,
cowidev.vax.batch.lithuania,1.31,True,2022-07-02T07:00:23,,
cowidev.vax.batch.luxembourg,1.79,True,2022-07-02T07:00:24,,
cowidev.vax.batch.malaysia,1.84,True,2022-07-02T07:00:25,,
cowidev.vax.batch.malta,1.86,True,2022-07-02T07:00:25,,
cowidev.vax.batch.netherlands,0.55,True,2022-07-02T09:06:22,,
cowidev.vax.batch.new_zealand,15.05,True,2022-07-02T07:00:40,,
cowidev.vax.batch.norway,1.35,True,2022-07-02T07:00:27,,
cowidev.vax.batch.peru,2.63,True,2022-07-02T07:00:30,,
cowidev.vax.batch.portugal,,,2022-07-02T07:00:30,,
cowidev.vax.batch.romania,19.18,True,2022-07-02T07:00:49,,
cowidev.vax.batch.saudi_arabia,6.4,True,2022-07-02T07:00:47,,
cowidev.vax.batch.singapore,2.25,True,2022-07-02T07:00:47,,
cowidev.vax.batch.slovakia,31.7,True,2022-07-02T07:01:19,,
cowidev.vax.batch.slovenia,1.37,True,2022-07-02T07:00:48,,
cowidev.vax.batch.south_korea,30.45,True,2022-07-02T07:01:19,,
cowidev.vax.batch.spc,16.66,True,2022-07-02T07:01:05,,
cowidev.vax.batch.sweden,11.69,True,2022-07-02T07:01:02,,
cowidev.vax.batch.switzerland,19.76,True,2022-07-02T07:01:12,,
cowidev.vax.batch.trinidad_and_tobago,2.03,True,2022-07-02T07:01:04,,
cowidev.vax.batch.ukraine,,,2022-07-02T07:01:04,,
cowidev.vax.batch.united_kingdom,9.11,True,2022-07-02T07:01:13,,
cowidev.vax.batch.united_states,17.97,True,2022-07-02T07:01:23,,
cowidev.vax.batch.uruguay,3.76,True,2022-07-02T07:01:16,,
cowidev.vax.batch.zimbabwe,0.63,True,2022-07-02T07:01:14,,
cowidev.vax.incremental.africacdc,,,2022-07-02T07:01:14,,
cowidev.vax.incremental.antigua_barbuda,6.81,True,2022-07-02T07:01:20,,
cowidev.vax.incremental.aruba,2.25,True,2022-07-02T07:01:18,,
cowidev.vax.incremental.azerbaijan,6.88,True,2022-07-02T07:01:25,,
cowidev.vax.incremental.bahrain,1.05,True,2022-07-02T07:01:20,,
cowidev.vax.incremental.bangladesh,13.03,True,2022-07-02T07:01:32,,
cowidev.vax.incremental.barbados,2.36,True,2022-07-02T07:01:22,,
cowidev.vax.incremental.brazil,0.05,True,2022-07-02T07:01:21,,
cowidev.vax.incremental.bulgaria,0.82,True,2022-07-02T07:01:21,,
cowidev.vax.incremental.china,26.86,True,2022-07-02T07:01:48,,
cowidev.vax.incremental.costa_rica,,,2022-07-02T07:01:22,,
cowidev.vax.incremental.croatia,0.18,True,2022-07-02T07:01:22,,
cowidev.vax.incremental.cuba,2.77,True,2022-07-02T07:01:25,,
cowidev.vax.incremental.curacao,0.35,True,2022-07-02T07:01:24,,
cowidev.vax.incremental.cyprus,1.25,True,2022-07-02T07:01:25,,
cowidev.vax.incremental.dominican_republic,6.29,True,2022-07-02T07:01:31,,
cowidev.vax.incremental.el_salvador,1.06,True,2022-07-02T07:01:26,,
cowidev.vax.incremental.faeroe_islands,0.37,True,2022-07-02T07:01:25,,
cowidev.vax.incremental.fiji,0.0,True,2022-07-02T07:01:25,,
cowidev.vax.incremental.finland,0.18,True,2022-07-02T07:01:26,,
cowidev.vax.incremental.gabon,,,2022-07-02T07:01:26,,
cowidev.vax.incremental.georgia,0.63,True,2022-07-02T07:01:26,,
cowidev.vax.incremental.greenland,0.43,True,2022-07-02T07:01:26,,
cowidev.vax.incremental.guatemala,,,2022-07-02T07:01:26,,
cowidev.vax.incremental.guernsey,0.24,True,2022-07-02T07:01:26,,
cowidev.vax.incremental.hungary,0.8,True,2022-07-02T07:01:27,,
cowidev.vax.incremental.iceland,0.19,True,2022-07-02T07:01:27,,
cowidev.vax.incremental.india,0.88,True,2022-07-02T07:01:28,,
cowidev.vax.incremental.iran,1.91,True,2022-07-02T07:01:29,,
cowidev.vax.incremental.isle_of_man,1.19,True,2022-07-02T07:01:29,,
cowidev.vax.incremental.jamaica,1.47,True,2022-07-02T07:01:30,,
cowidev.vax.incremental.kazakhstan,7.87,True,2022-07-02T07:01:37,,
cowidev.vax.incremental.kosovo,0.2,False,2022-07-02T07:03:09,"Traceback (most recent call last):
  File ""/mnt/owid_live_covid/covid-19-data/scripts/venv/lib/python3.9/site-packages/urllib3/connectionpool.py"", line 699, in urlopen
    httplib_response = self._make_request(
  File ""/mnt/owid_live_covid/covid-19-data/scripts/venv/lib/python3.9/site-packages/urllib3/connectionpool.py"", line 382, in _make_request
    self._validate_conn(conn)
  File ""/mnt/owid_live_covid/covid-19-data/scripts/venv/lib/python3.9/site-packages/urllib3/connectionpool.py"", line 1010, in _validate_conn
    conn.connect()
  File ""/mnt/owid_live_covid/covid-19-data/scripts/venv/lib/python3.9/site-packages/urllib3/connection.py"", line 416, in connect
    self.sock = ssl_wrap_socket(
  File ""/mnt/owid_live_covid/covid-19-data/scripts/venv/lib/python3.9/site-packages/urllib3/util/ssl_.py"", line 449, in ssl_wrap_socket
    ssl_sock = _ssl_wrap_socket_impl(
  File ""/mnt/owid_live_covid/covid-19-data/scripts/venv/lib/python3.9/site-packages/urllib3/util/ssl_.py"", line 493, in _ssl_wrap_socket_impl
    return ssl_context.wrap_socket(sock, server_hostname=server_hostname)
  File ""/home/owid/.pyenv/versions/3.9.6/lib/python3.9/ssl.py"", line 500, in wrap_socket
    return self.sslsocket_class._create(
  File ""/home/owid/.pyenv/versions/3.9.6/lib/python3.9/ssl.py"", line 1040, in _create
    self.do_handshake()
  File ""/home/owid/.pyenv/versions/3.9.6/lib/python3.9/ssl.py"", line 1309, in do_handshake
    self._sslobj.do_handshake()
ssl.SSLCertVerificationError: [SSL: CERTIFICATE_VERIFY_FAILED] certificate verify failed: unable to get local issuer certificate (_ssl.c:1129)

During handling of the above exception, another exception occurred:

Traceback (most recent call last):
  File ""/mnt/owid_live_covid/covid-19-data/scripts/venv/lib/python3.9/site-packages/requests/adapters.py"", line 440, in send
    resp = conn.urlopen(
  File ""/mnt/owid_live_covid/covid-19-data/scripts/venv/lib/python3.9/site-packages/urllib3/connectionpool.py"", line 755, in urlopen
    retries = retries.increment(
  File ""/mnt/owid_live_covid/covid-19-data/scripts/venv/lib/python3.9/site-packages/urllib3/util/retry.py"", line 574, in increment
    raise MaxRetryError(_pool, url, error or ResponseError(cause))
urllib3.exceptions.MaxRetryError: HTTPSConnectionPool(host='msh.rks-gov.net', port=443): Max retries exceeded with url: /sq/statistikat-covid-19/ (Caused by SSLError(SSLCertVerificationError(1, '[SSL: CERTIFICATE_VERIFY_FAILED] certificate verify failed: unable to get local issuer certificate (_ssl.c:1129)')))

During handling of the above exception, another exception occurred:

Traceback (most recent call last):
  File ""/mnt/owid_live_covid/covid-19-data/scripts/src/cowidev/cmd/commons/get.py"", line 47, in run
    module.main()
  File ""/mnt/owid_live_covid/covid-19-data/scripts/src/cowidev/vax/incremental/kosovo.py"", line 82, in main
    Kosovo().export()
  File ""/mnt/owid_live_covid/covid-19-data/scripts/src/cowidev/vax/incremental/kosovo.py"", line 77, in export
    df = self.read().pipe(self.pipeline)
  File ""/mnt/owid_live_covid/covid-19-data/scripts/src/cowidev/vax/incremental/kosovo.py"", line 22, in read
    soup = get_soup(self.source_url)
  File ""/mnt/owid_live_covid/covid-19-data/scripts/src/cowidev/utils/web/scraping.py"", line 83, in get_soup
    response = get_response(source, request_method, use_proxy, **kwargs)
  File ""/mnt/owid_live_covid/covid-19-data/scripts/src/cowidev/utils/web/scraping.py"", line 49, in get_response
    raise err
  File ""/mnt/owid_live_covid/covid-19-data/scripts/src/cowidev/utils/web/scraping.py"", line 43, in get_response
    response = requests.get(source, **kwargs)
  File ""/mnt/owid_live_covid/covid-19-data/scripts/venv/lib/python3.9/site-packages/requests/api.py"", line 75, in get
    return request('get', url, params=params, **kwargs)
  File ""/mnt/owid_live_covid/covid-19-data/scripts/venv/lib/python3.9/site-packages/requests/api.py"", line 61, in request
    return session.request(method=method, url=url, **kwargs)
  File ""/mnt/owid_live_covid/covid-19-data/scripts/venv/lib/python3.9/site-packages/requests/sessions.py"", line 529, in request
    resp = self.send(prep, **send_kwargs)
  File ""/mnt/owid_live_covid/covid-19-data/scripts/venv/lib/python3.9/site-packages/requests/sessions.py"", line 645, in send
    r = adapter.send(request, **kwargs)
  File ""/mnt/owid_live_covid/covid-19-data/scripts/venv/lib/python3.9/site-packages/requests/adapters.py"", line 517, in send
    raise SSLError(e, request=request)
requests.exceptions.SSLError: HTTPSConnectionPool(host='msh.rks-gov.net', port=443): Max retries exceeded with url: /sq/statistikat-covid-19/ (Caused by SSLError(SSLCertVerificationError(1, '[SSL: CERTIFICATE_VERIFY_FAILED] certificate verify failed: unable to get local issuer certificate (_ssl.c:1129)')))
","HTTPSConnectionPool(host='msh.rks-gov.net', port=443): Max retries exceeded with url: /sq/statistikat-covid-19/ (Caused by SSLError(SSLCertVerificationError(1, '[SSL: CERTIFICATE_VERIFY_FAILED] certificate verify failed: unable to get local issuer certificate (_ssl.c:1129)')))"
cowidev.vax.incremental.kyrgyzstan,0.92,True,2022-07-02T07:01:31,,
cowidev.vax.incremental.laos,2.91,True,2022-07-02T07:01:34,,
cowidev.vax.incremental.macao,15.42,True,2022-07-02T07:01:47,,
cowidev.vax.incremental.moldova,0.87,True,2022-07-02T07:01:33,,
cowidev.vax.incremental.monaco,27.54,True,2022-07-02T07:02:00,,
cowidev.vax.incremental.mongolia,0.99,True,2022-07-02T07:01:35,,
cowidev.vax.incremental.montenegro,0.08,True,2022-07-02T07:01:35,,
cowidev.vax.incremental.morocco,,,2022-07-02T07:01:35,,
cowidev.vax.incremental.myanmar,,,2022-07-02T07:01:35,,
cowidev.vax.incremental.nepal,3.76,False,2022-07-02T07:03:13,"Traceback (most recent call last):
  File ""/mnt/owid_live_covid/covid-19-data/scripts/src/cowidev/cmd/commons/get.py"", line 47, in run
    module.main()
  File ""/mnt/owid_live_covid/covid-19-data/scripts/src/cowidev/vax/incremental/nepal.py"", line 173, in main
    Nepal().export()
  File ""/mnt/owid_live_covid/covid-19-data/scripts/src/cowidev/vax/incremental/nepal.py"", line 155, in export
    df_main, df_manufacturer = self.read()
  File ""/mnt/owid_live_covid/covid-19-data/scripts/src/cowidev/vax/incremental/nepal.py"", line 28, in read
    links = request_json(self.source_url[""api""])
  File ""/mnt/owid_live_covid/covid-19-data/scripts/src/cowidev/utils/web/scraping.py"", line 106, in request_json
    text = request_text(url, **kwargs)
  File ""/mnt/owid_live_covid/covid-19-data/scripts/src/cowidev/utils/web/scraping.py"", line 127, in request_text
    soup = get_soup(url, **kwargs)
  File ""/mnt/owid_live_covid/covid-19-data/scripts/src/cowidev/utils/web/scraping.py"", line 83, in get_soup
    response = get_response(source, request_method, use_proxy, **kwargs)
  File ""/mnt/owid_live_covid/covid-19-data/scripts/src/cowidev/utils/web/scraping.py"", line 52, in get_response
    raise ValueError(
ValueError: Source https://covid19.mohp.gov.np/covid/api/ministryrelease not reached! Error code 502 Bad Gateway
",Source https://covid19.mohp.gov.np/covid/api/ministryrelease not reached! Error code 502 Bad Gateway
cowidev.vax.incremental.north_macedonia,,,2022-07-02T07:01:37,,
cowidev.vax.incremental.northern_cyprus,0.83,True,2022-07-02T07:01:38,,
cowidev.vax.incremental.paho,50.83,True,2022-07-02T07:02:29,,
cowidev.vax.incremental.pakistan,1.76,True,2022-07-02T07:01:40,,
cowidev.vax.incremental.philippines,,,2022-07-02T07:01:40,,
cowidev.vax.incremental.poland,0.17,True,2022-07-02T07:01:40,,
cowidev.vax.incremental.qatar,,,2022-07-02T07:01:40,,
cowidev.vax.incremental.russia,2.47,False,2022-07-02T07:03:15,"Traceback (most recent call last):
  File ""/mnt/owid_live_covid/covid-19-data/scripts/src/cowidev/cmd/commons/get.py"", line 47, in run
    module.main()
  File ""/mnt/owid_live_covid/covid-19-data/scripts/src/cowidev/vax/incremental/russia.py"", line 64, in main
    data = read(source).pipe(pipeline)
  File ""/mnt/owid_live_covid/covid-19-data/scripts/src/cowidev/vax/incremental/russia.py"", line 11, in read
    soup = get_soup(source)
  File ""/mnt/owid_live_covid/covid-19-data/scripts/src/cowidev/utils/web/scraping.py"", line 83, in get_soup
    response = get_response(source, request_method, use_proxy, **kwargs)
  File ""/mnt/owid_live_covid/covid-19-data/scripts/src/cowidev/utils/web/scraping.py"", line 52, in get_response
    raise ValueError(
ValueError: Source https://gogov.ru/articles/covid-v-stats not reached! Error code 502 Bad Gateway
",Source https://gogov.ru/articles/covid-v-stats not reached! Error code 502 Bad Gateway
cowidev.vax.incremental.saint_lucia,,,2022-07-02T07:01:42,,
cowidev.vax.incremental.serbia,26.58,True,2022-07-02T07:02:09,,
cowidev.vax.incremental.south_africa,8.02,True,2022-07-02T07:01:55,,
cowidev.vax.incremental.spain,5.01,True,2022-07-02T07:01:53,,
cowidev.vax.incremental.sri_lanka,,,2022-07-02T07:01:53,,
cowidev.vax.incremental.suriname,13.84,True,2022-07-02T07:02:07,,
cowidev.vax.incremental.taiwan,6.41,True,2022-07-02T07:02:01,,
cowidev.vax.incremental.thailand,1.54,True,2022-07-02T07:02:02,,
cowidev.vax.incremental.turkey,0.49,True,2022-07-02T07:02:02,,
cowidev.vax.incremental.united_arab_emirates,,,2022-07-02T07:02:02,,
cowidev.vax.incremental.vietnam,2.41,True,2022-07-02T07:02:04,,
cowidev.vax.incremental.who,2.73,True,2022-07-02T07:02:05,,
cowidev.vax.incremental.zambia,1.01,True,2022-07-02T07:02:05,,
