module,execution_time (sec),success,timestamp,error,error_short
cowidev.vax.batch.argentina,3.58,True,2022-09-19T07:00:15,,
cowidev.vax.batch.australia,1.81,True,2022-09-19T07:00:13,,
cowidev.vax.batch.austria,130.84,True,2022-09-19T07:02:22,,
cowidev.vax.batch.belgium,2.08,True,2022-09-19T07:00:13,,
cowidev.vax.batch.bolivia,2.16,True,2022-09-19T07:00:14,,
cowidev.vax.batch.canada,7.21,False,2022-09-19T07:03:14,"Traceback (most recent call last):
  File ""/mnt/owid_live_covid/covid-19-data/scripts/src/cowidev/cmd/commons/get.py"", line 47, in run
    module.main()
  File ""/mnt/owid_live_covid/covid-19-data/scripts/src/cowidev/vax/batch/canada.py"", line 260, in main
    Canada().export()
  File ""/mnt/owid_live_covid/covid-19-data/scripts/src/cowidev/vax/batch/canada.py"", line 247, in export
    df_man = df_man.pipe(self.pipeline_manufacturer)
  File ""/mnt/owid_live_covid/covid-19-data/scripts/venv/lib/python3.9/site-packages/pandas/core/generic.py"", line 5430, in pipe
    return com.pipe(self, func, *args, **kwargs)
  File ""/mnt/owid_live_covid/covid-19-data/scripts/venv/lib/python3.9/site-packages/pandas/core/common.py"", line 471, in pipe
    return func(obj, *args, **kwargs)
  File ""/mnt/owid_live_covid/covid-19-data/scripts/src/cowidev/vax/batch/canada.py"", line 179, in pipeline_manufacturer
    df = df[df.total_vaccinations > 0].replace(self.vaccine_mapping).dropna()
  File ""/mnt/owid_live_covid/covid-19-data/scripts/venv/lib/python3.9/site-packages/pandas/core/ops/common.py"", line 69, in new_method
    return method(self, other)
  File ""/mnt/owid_live_covid/covid-19-data/scripts/venv/lib/python3.9/site-packages/pandas/core/arraylike.py"", line 48, in __gt__
    return self._cmp_method(other, operator.gt)
  File ""/mnt/owid_live_covid/covid-19-data/scripts/venv/lib/python3.9/site-packages/pandas/core/series.py"", line 5502, in _cmp_method
    res_values = ops.comparison_op(lvalues, rvalues, op)
  File ""/mnt/owid_live_covid/covid-19-data/scripts/venv/lib/python3.9/site-packages/pandas/core/ops/array_ops.py"", line 284, in comparison_op
    res_values = comp_method_OBJECT_ARRAY(op, lvalues, rvalues)
  File ""/mnt/owid_live_covid/covid-19-data/scripts/venv/lib/python3.9/site-packages/pandas/core/ops/array_ops.py"", line 73, in comp_method_OBJECT_ARRAY
    result = libops.scalar_compare(x.ravel(), y, op)
  File ""pandas/_libs/ops.pyx"", line 107, in pandas._libs.ops.scalar_compare
TypeError: '>' not supported between instances of 'str' and 'int'
",'>' not supported between instances of 'str' and 'int'
cowidev.vax.batch.chile,0.63,True,2022-09-19T07:00:14,,
cowidev.vax.batch.czechia,4.1,True,2022-09-19T07:00:18,,
cowidev.vax.batch.denmark,3.6,True,2022-09-19T07:00:18,,
cowidev.vax.batch.ecdc,90.73,True,2022-09-19T07:01:46,,
cowidev.vax.batch.ecuador,1.31,True,2022-09-19T07:00:19,,
cowidev.vax.batch.estonia,0.53,True,2022-09-19T07:00:18,,
cowidev.vax.batch.france,0.49,True,2022-09-19T07:00:19,,
cowidev.vax.batch.germany,1.75,True,2022-09-19T07:00:20,,
cowidev.vax.batch.greece,2.73,True,2022-09-19T07:00:22,,
cowidev.vax.batch.hong_kong,14.32,True,2022-09-19T07:00:35,,
cowidev.vax.batch.indonesia,,,2022-09-19T07:00:22,,
cowidev.vax.batch.ireland,0.42,True,2022-09-19T07:00:22,,
cowidev.vax.batch.israel,8.58,True,2022-09-19T07:00:31,,
cowidev.vax.batch.italy,0.91,False,2022-09-19T07:03:15,"Traceback (most recent call last):
  File ""/mnt/owid_live_covid/covid-19-data/scripts/src/cowidev/cmd/commons/get.py"", line 47, in run
    module.main()
  File ""/mnt/owid_live_covid/covid-19-data/scripts/src/cowidev/vax/batch/italy.py"", line 167, in main
    Italy().export()
  File ""/mnt/owid_live_covid/covid-19-data/scripts/src/cowidev/vax/batch/italy.py"", line 149, in export
    df_base = self.read().pipe(self.pipeline_base)
  File ""/mnt/owid_live_covid/covid-19-data/scripts/src/cowidev/vax/batch/italy.py"", line 45, in read
    return df[self.columns]
  File ""/mnt/owid_live_covid/covid-19-data/scripts/venv/lib/python3.9/site-packages/pandas/core/frame.py"", line 3464, in __getitem__
    indexer = self.loc._get_listlike_indexer(key, axis=1)[1]
  File ""/mnt/owid_live_covid/covid-19-data/scripts/venv/lib/python3.9/site-packages/pandas/core/indexing.py"", line 1314, in _get_listlike_indexer
    self._validate_read_indexer(keyarr, indexer, axis)
  File ""/mnt/owid_live_covid/covid-19-data/scripts/venv/lib/python3.9/site-packages/pandas/core/indexing.py"", line 1377, in _validate_read_indexer
    raise KeyError(f""{not_found} not in index"")
KeyError: ""['dbi'] not in index""
","""['dbi'] not in index"""
cowidev.vax.batch.japan,1.2,False,2022-09-19T07:03:16,"Traceback (most recent call last):
  File ""/mnt/owid_live_covid/covid-19-data/scripts/src/cowidev/cmd/commons/get.py"", line 47, in run
    module.main()
  File ""/mnt/owid_live_covid/covid-19-data/scripts/src/cowidev/vax/batch/japan.py"", line 236, in main
    Japan().export()
  File ""/mnt/owid_live_covid/covid-19-data/scripts/src/cowidev/vax/batch/japan.py"", line 220, in export
    df = self.read().pipe(self.pipeline_base)
  File ""/mnt/owid_live_covid/covid-19-data/scripts/src/cowidev/vax/batch/japan.py"", line 156, in read
    df_latest = self.read_latest().pipe(self.pipe_latest)
  File ""/mnt/owid_live_covid/covid-19-data/scripts/src/cowidev/vax/batch/japan.py"", line 88, in read_latest
    dfs.append(self._read_xlsx(self.source_url, self.sheets, self.metrics))
  File ""/mnt/owid_live_covid/covid-19-data/scripts/src/cowidev/vax/batch/japan.py"", line 97, in _read_xlsx
    xlsx = pd.ExcelFile(url)
  File ""/mnt/owid_live_covid/covid-19-data/scripts/venv/lib/python3.9/site-packages/pandas/io/excel/_base.py"", line 1191, in __init__
    ext = inspect_excel_format(
  File ""/mnt/owid_live_covid/covid-19-data/scripts/venv/lib/python3.9/site-packages/pandas/io/excel/_base.py"", line 1070, in inspect_excel_format
    with get_handle(
  File ""/mnt/owid_live_covid/covid-19-data/scripts/venv/lib/python3.9/site-packages/pandas/io/common.py"", line 609, in get_handle
    ioargs = _get_filepath_or_buffer(
  File ""/mnt/owid_live_covid/covid-19-data/scripts/venv/lib/python3.9/site-packages/pandas/io/common.py"", line 312, in _get_filepath_or_buffer
    with urlopen(req_info) as req:
  File ""/mnt/owid_live_covid/covid-19-data/scripts/venv/lib/python3.9/site-packages/pandas/io/common.py"", line 212, in urlopen
    return urllib.request.urlopen(*args, **kwargs)
  File ""/home/owid/.pyenv/versions/3.9.6/lib/python3.9/urllib/request.py"", line 214, in urlopen
    return opener.open(url, data, timeout)
  File ""/home/owid/.pyenv/versions/3.9.6/lib/python3.9/urllib/request.py"", line 523, in open
    response = meth(req, response)
  File ""/home/owid/.pyenv/versions/3.9.6/lib/python3.9/urllib/request.py"", line 632, in http_response
    response = self.parent.error(
  File ""/home/owid/.pyenv/versions/3.9.6/lib/python3.9/urllib/request.py"", line 561, in error
    return self._call_chain(*args)
  File ""/home/owid/.pyenv/versions/3.9.6/lib/python3.9/urllib/request.py"", line 494, in _call_chain
    result = func(*args)
  File ""/home/owid/.pyenv/versions/3.9.6/lib/python3.9/urllib/request.py"", line 641, in http_error_default
    raise HTTPError(req.full_url, code, msg, hdrs, fp)
urllib.error.HTTPError: HTTP Error 404: Not Found
",HTTP Error 404: Not Found
cowidev.vax.batch.jersey,1.82,True,2022-09-19T07:00:32,,
cowidev.vax.batch.latvia,38.46,True,2022-09-19T07:01:11,,
cowidev.vax.batch.lithuania,2.18,True,2022-09-19T07:00:37,,
cowidev.vax.batch.luxembourg,12.3,True,2022-09-19T07:00:49,,
cowidev.vax.batch.malaysia,2.48,True,2022-09-19T07:00:49,,
cowidev.vax.batch.malta,1.37,True,2022-09-19T07:00:50,,
cowidev.vax.batch.netherlands,,,2022-09-19T07:00:49,,
cowidev.vax.batch.new_zealand,27.7,True,2022-09-19T07:01:17,,
cowidev.vax.batch.norway,1.43,True,2022-09-19T07:00:51,,
cowidev.vax.batch.peru,3.49,True,2022-09-19T07:00:55,,
cowidev.vax.batch.portugal,,,2022-09-19T07:00:55,,
cowidev.vax.batch.romania,29.53,True,2022-09-19T07:01:24,,
cowidev.vax.batch.saudi_arabia,5.02,True,2022-09-19T07:01:16,,
cowidev.vax.batch.singapore,2.04,True,2022-09-19T07:01:18,,
cowidev.vax.batch.slovakia,53.29,True,2022-09-19T07:02:10,,
cowidev.vax.batch.slovenia,1.57,True,2022-09-19T07:01:20,,
cowidev.vax.batch.south_korea,44.73,True,2022-09-19T07:02:04,,
cowidev.vax.batch.spc,16.44,True,2022-09-19T07:01:41,,
cowidev.vax.batch.sweden,13.8,True,2022-09-19T07:01:55,,
cowidev.vax.batch.switzerland,25.35,True,2022-09-19T07:02:11,,
cowidev.vax.batch.trinidad_and_tobago,2.01,True,2022-09-19T07:01:57,,
cowidev.vax.batch.ukraine,,,2022-09-19T07:01:57,,
cowidev.vax.batch.united_kingdom,8.94,True,2022-09-19T07:02:06,,
cowidev.vax.batch.united_states,15.18,True,2022-09-19T07:02:19,,
cowidev.vax.batch.uruguay,4.44,True,2022-09-19T07:02:10,,
cowidev.vax.batch.zimbabwe,0.85,True,2022-09-19T07:02:11,,
cowidev.vax.incremental.africacdc,,,2022-09-19T07:02:10,,
cowidev.vax.incremental.antigua_barbuda,6.44,True,2022-09-19T07:02:17,,
cowidev.vax.incremental.aruba,0.91,True,2022-09-19T07:02:12,,
cowidev.vax.incremental.azerbaijan,,,2022-09-19T07:02:11,,
cowidev.vax.incremental.bahrain,1.23,True,2022-09-19T07:02:12,,
cowidev.vax.incremental.bangladesh,42.06,False,2022-09-19T07:03:58,"Traceback (most recent call last):
  File ""/mnt/owid_live_covid/covid-19-data/scripts/src/cowidev/cmd/commons/get.py"", line 47, in run
    module.main()
  File ""/mnt/owid_live_covid/covid-19-data/scripts/src/cowidev/vax/incremental/bangladesh.py"", line 111, in main
    Bangladesh().export()
  File ""/mnt/owid_live_covid/covid-19-data/scripts/src/cowidev/vax/incremental/bangladesh.py"", line 97, in export
    data = self.read().pipe(self.pipeline)
  File ""/mnt/owid_live_covid/covid-19-data/scripts/src/cowidev/vax/incremental/bangladesh.py"", line 25, in read
    vaccines = self._parse_vaccines(soup)
  File ""/mnt/owid_live_covid/covid-19-data/scripts/src/cowidev/vax/incremental/bangladesh.py"", line 81, in _parse_vaccines
    raise ValueError(f""Unknown vaccines found {vaccines_unk}"")
ValueError: Unknown vaccines found {'Pfizer-PF (Comirnaty)'}
",Unknown vaccines found {'Pfizer-PF (Comirnaty)'}
cowidev.vax.incremental.barbados,1.62,True,2022-09-19T07:02:14,,
cowidev.vax.incremental.brazil,0.06,True,2022-09-19T07:02:14,,
cowidev.vax.incremental.bulgaria,1.06,True,2022-09-19T07:02:15,,
cowidev.vax.incremental.china,49.58,True,2022-09-19T07:03:05,,
cowidev.vax.incremental.costa_rica,,,2022-09-19T07:02:17,,
cowidev.vax.incremental.croatia,0.14,True,2022-09-19T07:02:17,,
cowidev.vax.incremental.cuba,2.21,True,2022-09-19T07:02:19,,
cowidev.vax.incremental.curacao,0.42,True,2022-09-19T07:02:19,,
cowidev.vax.incremental.cyprus,0.97,True,2022-09-19T07:02:20,,
cowidev.vax.incremental.dominican_republic,3.37,False,2022-09-19T07:04:02,"Traceback (most recent call last):
  File ""/mnt/owid_live_covid/covid-19-data/scripts/src/cowidev/cmd/commons/get.py"", line 47, in run
    module.main()
  File ""/mnt/owid_live_covid/covid-19-data/scripts/src/cowidev/vax/incremental/dominican_republic.py"", line 108, in main
    DominicanRepublic().export()
  File ""/mnt/owid_live_covid/covid-19-data/scripts/src/cowidev/vax/incremental/dominican_republic.py"", line 64, in export
    data = self.read().pipe(self.pipeline)
  File ""/mnt/owid_live_covid/covid-19-data/scripts/src/cowidev/vax/incremental/dominican_republic.py"", line 23, in read
    with webdriver.Chrome(options=op) as driver:
  File ""/mnt/owid_live_covid/covid-19-data/scripts/venv/lib/python3.9/site-packages/selenium/webdriver/chrome/webdriver.py"", line 76, in __init__
    RemoteWebDriver.__init__(
  File ""/mnt/owid_live_covid/covid-19-data/scripts/venv/lib/python3.9/site-packages/selenium/webdriver/remote/webdriver.py"", line 157, in __init__
    self.start_session(capabilities, browser_profile)
  File ""/mnt/owid_live_covid/covid-19-data/scripts/venv/lib/python3.9/site-packages/selenium/webdriver/remote/webdriver.py"", line 252, in start_session
    response = self.execute(Command.NEW_SESSION, parameters)
  File ""/mnt/owid_live_covid/covid-19-data/scripts/venv/lib/python3.9/site-packages/selenium/webdriver/remote/webdriver.py"", line 321, in execute
    self.error_handler.check_response(response)
  File ""/mnt/owid_live_covid/covid-19-data/scripts/venv/lib/python3.9/site-packages/selenium/webdriver/remote/errorhandler.py"", line 242, in check_response
    raise exception_class(message, screen, stacktrace)
selenium.common.exceptions.SessionNotCreatedException: Message: session not created: This version of ChromeDriver only supports Chrome version 103
Current browser version is 105.0.5195.102 with binary path /usr/bin/chromium-browser

","Message: session not created: This version of ChromeDriver only supports Chrome version 103
Current browser version is 105.0.5195.102 with binary path /usr/bin/chromium-browser
"
cowidev.vax.incremental.el_salvador,0.53,True,2022-09-19T07:02:21,,
cowidev.vax.incremental.faeroe_islands,0.4,True,2022-09-19T07:02:21,,
cowidev.vax.incremental.fiji,0.0,True,2022-09-19T07:02:21,,
cowidev.vax.incremental.finland,0.2,True,2022-09-19T07:02:22,,
cowidev.vax.incremental.gabon,,,2022-09-19T07:02:22,,
cowidev.vax.incremental.georgia,0.49,True,2022-09-19T07:02:22,,
cowidev.vax.incremental.greenland,0.67,True,2022-09-19T07:02:23,,
cowidev.vax.incremental.guatemala,,,2022-09-19T07:02:22,,
cowidev.vax.incremental.guernsey,0.12,True,2022-09-19T07:02:22,,
cowidev.vax.incremental.hungary,0.94,True,2022-09-19T07:02:23,,
cowidev.vax.incremental.iceland,0.42,True,2022-09-19T07:02:23,,
cowidev.vax.incremental.india,0.93,True,2022-09-19T07:02:24,,
cowidev.vax.incremental.iran,,,2022-09-19T07:02:23,,
cowidev.vax.incremental.isle_of_man,0.8,True,2022-09-19T07:02:24,,
cowidev.vax.incremental.jamaica,2.41,True,2022-09-19T07:02:26,,
cowidev.vax.incremental.kazakhstan,2.5,False,2022-09-19T07:04:04,"Traceback (most recent call last):
  File ""/mnt/owid_live_covid/covid-19-data/scripts/src/cowidev/cmd/commons/get.py"", line 47, in run
    module.main()
  File ""/mnt/owid_live_covid/covid-19-data/scripts/src/cowidev/vax/incremental/kazakhstan.py"", line 78, in main
    Kazakhstan().export()
  File ""/mnt/owid_live_covid/covid-19-data/scripts/src/cowidev/vax/incremental/kazakhstan.py"", line 73, in export
    df = self.read().pipe(self.pipeline)
  File ""/mnt/owid_live_covid/covid-19-data/scripts/src/cowidev/vax/incremental/kazakhstan.py"", line 17, in read
    with webdriver.Chrome(options=op) as driver:
  File ""/mnt/owid_live_covid/covid-19-data/scripts/venv/lib/python3.9/site-packages/selenium/webdriver/chrome/webdriver.py"", line 76, in __init__
    RemoteWebDriver.__init__(
  File ""/mnt/owid_live_covid/covid-19-data/scripts/venv/lib/python3.9/site-packages/selenium/webdriver/remote/webdriver.py"", line 157, in __init__
    self.start_session(capabilities, browser_profile)
  File ""/mnt/owid_live_covid/covid-19-data/scripts/venv/lib/python3.9/site-packages/selenium/webdriver/remote/webdriver.py"", line 252, in start_session
    response = self.execute(Command.NEW_SESSION, parameters)
  File ""/mnt/owid_live_covid/covid-19-data/scripts/venv/lib/python3.9/site-packages/selenium/webdriver/remote/webdriver.py"", line 321, in execute
    self.error_handler.check_response(response)
  File ""/mnt/owid_live_covid/covid-19-data/scripts/venv/lib/python3.9/site-packages/selenium/webdriver/remote/errorhandler.py"", line 242, in check_response
    raise exception_class(message, screen, stacktrace)
selenium.common.exceptions.SessionNotCreatedException: Message: session not created: This version of ChromeDriver only supports Chrome version 103
Current browser version is 105.0.5195.102 with binary path /usr/bin/chromium-browser

","Message: session not created: This version of ChromeDriver only supports Chrome version 103
Current browser version is 105.0.5195.102 with binary path /usr/bin/chromium-browser
"
cowidev.vax.incremental.kosovo,1.91,True,2022-09-19T07:02:26,,
cowidev.vax.incremental.kyrgyzstan,1.13,True,2022-09-19T07:02:27,,
cowidev.vax.incremental.laos,2.35,True,2022-09-19T07:02:28,,
cowidev.vax.incremental.macao,2.4,False,2022-09-19T07:04:07,"Traceback (most recent call last):
  File ""/mnt/owid_live_covid/covid-19-data/scripts/src/cowidev/cmd/commons/get.py"", line 47, in run
    module.main()
  File ""/mnt/owid_live_covid/covid-19-data/scripts/src/cowidev/vax/incremental/macao.py"", line 86, in main
    Macao().export()
  File ""/mnt/owid_live_covid/covid-19-data/scripts/src/cowidev/vax/incremental/macao.py"", line 72, in export
    data = self.read()
  File ""/mnt/owid_live_covid/covid-19-data/scripts/src/cowidev/vax/incremental/macao.py"", line 16, in read
    with get_driver() as driver:
  File ""/mnt/owid_live_covid/covid-19-data/scripts/src/cowidev/utils/web/scraping.py"", line 161, in get_driver
    driver = webdriver.Chrome(options=options)
  File ""/mnt/owid_live_covid/covid-19-data/scripts/venv/lib/python3.9/site-packages/selenium/webdriver/chrome/webdriver.py"", line 76, in __init__
    RemoteWebDriver.__init__(
  File ""/mnt/owid_live_covid/covid-19-data/scripts/venv/lib/python3.9/site-packages/selenium/webdriver/remote/webdriver.py"", line 157, in __init__
    self.start_session(capabilities, browser_profile)
  File ""/mnt/owid_live_covid/covid-19-data/scripts/venv/lib/python3.9/site-packages/selenium/webdriver/remote/webdriver.py"", line 252, in start_session
    response = self.execute(Command.NEW_SESSION, parameters)
  File ""/mnt/owid_live_covid/covid-19-data/scripts/venv/lib/python3.9/site-packages/selenium/webdriver/remote/webdriver.py"", line 321, in execute
    self.error_handler.check_response(response)
  File ""/mnt/owid_live_covid/covid-19-data/scripts/venv/lib/python3.9/site-packages/selenium/webdriver/remote/errorhandler.py"", line 242, in check_response
    raise exception_class(message, screen, stacktrace)
selenium.common.exceptions.SessionNotCreatedException: Message: session not created: This version of ChromeDriver only supports Chrome version 103
Current browser version is 105.0.5195.102 with binary path /usr/bin/chromium-browser

","Message: session not created: This version of ChromeDriver only supports Chrome version 103
Current browser version is 105.0.5195.102 with binary path /usr/bin/chromium-browser
"
cowidev.vax.incremental.moldova,40.03,False,2022-09-19T07:04:47,"Traceback (most recent call last):
  File ""/mnt/owid_live_covid/covid-19-data/scripts/venv/lib/python3.9/site-packages/urllib3/connection.py"", line 174, in _new_conn
    conn = connection.create_connection(
  File ""/mnt/owid_live_covid/covid-19-data/scripts/venv/lib/python3.9/site-packages/urllib3/util/connection.py"", line 96, in create_connection
    raise err
  File ""/mnt/owid_live_covid/covid-19-data/scripts/venv/lib/python3.9/site-packages/urllib3/util/connection.py"", line 86, in create_connection
    sock.connect(sa)
socket.timeout: timed out

During handling of the above exception, another exception occurred:

Traceback (most recent call last):
  File ""/mnt/owid_live_covid/covid-19-data/scripts/venv/lib/python3.9/site-packages/urllib3/connectionpool.py"", line 699, in urlopen
    httplib_response = self._make_request(
  File ""/mnt/owid_live_covid/covid-19-data/scripts/venv/lib/python3.9/site-packages/urllib3/connectionpool.py"", line 382, in _make_request
    self._validate_conn(conn)
  File ""/mnt/owid_live_covid/covid-19-data/scripts/venv/lib/python3.9/site-packages/urllib3/connectionpool.py"", line 1010, in _validate_conn
    conn.connect()
  File ""/mnt/owid_live_covid/covid-19-data/scripts/venv/lib/python3.9/site-packages/urllib3/connection.py"", line 358, in connect
    conn = self._new_conn()
  File ""/mnt/owid_live_covid/covid-19-data/scripts/venv/lib/python3.9/site-packages/urllib3/connection.py"", line 179, in _new_conn
    raise ConnectTimeoutError(
urllib3.exceptions.ConnectTimeoutError: (<urllib3.connection.HTTPSConnection object at 0x7fa95ab0c370>, 'Connection to vaccinare.gov.md timed out. (connect timeout=20)')

During handling of the above exception, another exception occurred:

Traceback (most recent call last):
  File ""/mnt/owid_live_covid/covid-19-data/scripts/venv/lib/python3.9/site-packages/requests/adapters.py"", line 440, in send
    resp = conn.urlopen(
  File ""/mnt/owid_live_covid/covid-19-data/scripts/venv/lib/python3.9/site-packages/urllib3/connectionpool.py"", line 755, in urlopen
    retries = retries.increment(
  File ""/mnt/owid_live_covid/covid-19-data/scripts/venv/lib/python3.9/site-packages/urllib3/util/retry.py"", line 574, in increment
    raise MaxRetryError(_pool, url, error or ResponseError(cause))
urllib3.exceptions.MaxRetryError: HTTPSConnectionPool(host='vaccinare.gov.md', port=443): Max retries exceeded with url: / (Caused by ConnectTimeoutError(<urllib3.connection.HTTPSConnection object at 0x7fa95ab0c370>, 'Connection to vaccinare.gov.md timed out. (connect timeout=20)'))

During handling of the above exception, another exception occurred:

Traceback (most recent call last):
  File ""/mnt/owid_live_covid/covid-19-data/scripts/src/cowidev/cmd/commons/get.py"", line 47, in run
    module.main()
  File ""/mnt/owid_live_covid/covid-19-data/scripts/src/cowidev/vax/incremental/moldova.py"", line 59, in main
    Moldova().export()
  File ""/mnt/owid_live_covid/covid-19-data/scripts/src/cowidev/vax/incremental/moldova.py"", line 54, in export
    df = self.read().pipe(self.pipeline)
  File ""/mnt/owid_live_covid/covid-19-data/scripts/src/cowidev/vax/incremental/moldova.py"", line 17, in read
    soup = get_soup(self.source_url)
  File ""/mnt/owid_live_covid/covid-19-data/scripts/src/cowidev/utils/web/scraping.py"", line 83, in get_soup
    response = get_response(source, request_method, use_proxy, **kwargs)
  File ""/mnt/owid_live_covid/covid-19-data/scripts/src/cowidev/utils/web/scraping.py"", line 49, in get_response
    raise err
  File ""/mnt/owid_live_covid/covid-19-data/scripts/src/cowidev/utils/web/scraping.py"", line 43, in get_response
    response = requests.get(source, **kwargs)
  File ""/mnt/owid_live_covid/covid-19-data/scripts/venv/lib/python3.9/site-packages/requests/api.py"", line 75, in get
    return request('get', url, params=params, **kwargs)
  File ""/mnt/owid_live_covid/covid-19-data/scripts/venv/lib/python3.9/site-packages/requests/api.py"", line 61, in request
    return session.request(method=method, url=url, **kwargs)
  File ""/mnt/owid_live_covid/covid-19-data/scripts/venv/lib/python3.9/site-packages/requests/sessions.py"", line 529, in request
    resp = self.send(prep, **send_kwargs)
  File ""/mnt/owid_live_covid/covid-19-data/scripts/venv/lib/python3.9/site-packages/requests/sessions.py"", line 645, in send
    r = adapter.send(request, **kwargs)
  File ""/mnt/owid_live_covid/covid-19-data/scripts/venv/lib/python3.9/site-packages/requests/adapters.py"", line 507, in send
    raise ConnectTimeout(e, request=request)
requests.exceptions.ConnectTimeout: HTTPSConnectionPool(host='vaccinare.gov.md', port=443): Max retries exceeded with url: / (Caused by ConnectTimeoutError(<urllib3.connection.HTTPSConnection object at 0x7fa95ab0c370>, 'Connection to vaccinare.gov.md timed out. (connect timeout=20)'))
","HTTPSConnectionPool(host='vaccinare.gov.md', port=443): Max retries exceeded with url: / (Caused by ConnectTimeoutError(<urllib3.connection.HTTPSConnection object at 0x7fa95ab0c370>, 'Connection to vaccinare.gov.md timed out. (connect timeout=20)'))"
cowidev.vax.incremental.monaco,31.46,True,2022-09-19T07:02:59,,
cowidev.vax.incremental.mongolia,0.68,True,2022-09-19T07:02:29,,
cowidev.vax.incremental.montenegro,0.09,True,2022-09-19T07:02:29,,
cowidev.vax.incremental.morocco,,,2022-09-19T07:02:29,,
cowidev.vax.incremental.myanmar,,,2022-09-19T07:02:29,,
cowidev.vax.incremental.nepal,,,2022-09-19T07:02:29,,
cowidev.vax.incremental.north_macedonia,,,2022-09-19T07:02:29,,
cowidev.vax.incremental.northern_cyprus,0.86,True,2022-09-19T07:02:30,,
cowidev.vax.incremental.paho,3.05,False,2022-09-19T07:04:50,"Traceback (most recent call last):
  File ""/mnt/owid_live_covid/covid-19-data/scripts/src/cowidev/cmd/commons/get.py"", line 47, in run
    module.main()
  File ""/mnt/owid_live_covid/covid-19-data/scripts/src/cowidev/vax/incremental/paho.py"", line 191, in main
    PAHO().export()
  File ""/mnt/owid_live_covid/covid-19-data/scripts/src/cowidev/vax/incremental/paho.py"", line 186, in export
    df = self.read().pipe(self.pipeline)
  File ""/mnt/owid_live_covid/covid-19-data/scripts/src/cowidev/vax/incremental/paho.py"", line 37, in read
    df = self._parse_data(url)
  File ""/mnt/owid_live_covid/covid-19-data/scripts/src/cowidev/vax/incremental/paho.py"", line 46, in _parse_data
    with get_driver(download_folder=self._download_path) as driver:
  File ""/mnt/owid_live_covid/covid-19-data/scripts/src/cowidev/utils/web/scraping.py"", line 161, in get_driver
    driver = webdriver.Chrome(options=options)
  File ""/mnt/owid_live_covid/covid-19-data/scripts/venv/lib/python3.9/site-packages/selenium/webdriver/chrome/webdriver.py"", line 76, in __init__
    RemoteWebDriver.__init__(
  File ""/mnt/owid_live_covid/covid-19-data/scripts/venv/lib/python3.9/site-packages/selenium/webdriver/remote/webdriver.py"", line 157, in __init__
    self.start_session(capabilities, browser_profile)
  File ""/mnt/owid_live_covid/covid-19-data/scripts/venv/lib/python3.9/site-packages/selenium/webdriver/remote/webdriver.py"", line 252, in start_session
    response = self.execute(Command.NEW_SESSION, parameters)
  File ""/mnt/owid_live_covid/covid-19-data/scripts/venv/lib/python3.9/site-packages/selenium/webdriver/remote/webdriver.py"", line 321, in execute
    self.error_handler.check_response(response)
  File ""/mnt/owid_live_covid/covid-19-data/scripts/venv/lib/python3.9/site-packages/selenium/webdriver/remote/errorhandler.py"", line 242, in check_response
    raise exception_class(message, screen, stacktrace)
selenium.common.exceptions.SessionNotCreatedException: Message: session not created: This version of ChromeDriver only supports Chrome version 103
Current browser version is 105.0.5195.102 with binary path /usr/bin/chromium-browser

","Message: session not created: This version of ChromeDriver only supports Chrome version 103
Current browser version is 105.0.5195.102 with binary path /usr/bin/chromium-browser
"
cowidev.vax.incremental.pakistan,1.61,True,2022-09-19T07:02:37,,
cowidev.vax.incremental.philippines,,,2022-09-19T07:02:37,,
cowidev.vax.incremental.poland,0.31,True,2022-09-19T07:02:37,,
cowidev.vax.incremental.qatar,,,2022-09-19T07:02:37,,
cowidev.vax.incremental.russia,0.46,False,2022-09-19T07:04:50,"Traceback (most recent call last):
  File ""/mnt/owid_live_covid/covid-19-data/scripts/src/cowidev/cmd/commons/get.py"", line 47, in run
    module.main()
  File ""/mnt/owid_live_covid/covid-19-data/scripts/src/cowidev/vax/incremental/russia.py"", line 80, in main
    Russia().export()
  File ""/mnt/owid_live_covid/covid-19-data/scripts/src/cowidev/vax/incremental/russia.py"", line 66, in export
    data = read(source).pipe(pipeline)
  File ""/mnt/owid_live_covid/covid-19-data/scripts/src/cowidev/vax/incremental/russia.py"", line 11, in read
    soup = get_soup(source)
  File ""/mnt/owid_live_covid/covid-19-data/scripts/src/cowidev/utils/web/scraping.py"", line 83, in get_soup
    response = get_response(source, request_method, use_proxy, **kwargs)
  File ""/mnt/owid_live_covid/covid-19-data/scripts/src/cowidev/utils/web/scraping.py"", line 52, in get_response
    raise ValueError(
ValueError: Source https://gogov.ru/articles/covid-v-stats not reached! Error code 502 Bad Gateway
",Source https://gogov.ru/articles/covid-v-stats not reached! Error code 502 Bad Gateway
cowidev.vax.incremental.saint_lucia,,,2022-09-19T07:02:38,,
cowidev.vax.incremental.serbia,5.7,True,2022-09-19T07:02:44,,
cowidev.vax.incremental.south_africa,6.48,True,2022-09-19T07:02:50,,
cowidev.vax.incremental.spain,3.46,True,2022-09-19T07:02:54,,
cowidev.vax.incremental.sri_lanka,,,2022-09-19T07:02:54,,
cowidev.vax.incremental.suriname,2.34,False,2022-09-19T07:04:52,"Traceback (most recent call last):
  File ""/mnt/owid_live_covid/covid-19-data/scripts/src/cowidev/cmd/commons/get.py"", line 47, in run
    module.main()
  File ""/mnt/owid_live_covid/covid-19-data/scripts/src/cowidev/vax/incremental/suriname.py"", line 57, in main
    data = read(source).pipe(pipeline)
  File ""/mnt/owid_live_covid/covid-19-data/scripts/src/cowidev/vax/incremental/suriname.py"", line 13, in read
    with get_driver() as driver:
  File ""/mnt/owid_live_covid/covid-19-data/scripts/src/cowidev/utils/web/scraping.py"", line 161, in get_driver
    driver = webdriver.Chrome(options=options)
  File ""/mnt/owid_live_covid/covid-19-data/scripts/venv/lib/python3.9/site-packages/selenium/webdriver/chrome/webdriver.py"", line 76, in __init__
    RemoteWebDriver.__init__(
  File ""/mnt/owid_live_covid/covid-19-data/scripts/venv/lib/python3.9/site-packages/selenium/webdriver/remote/webdriver.py"", line 157, in __init__
    self.start_session(capabilities, browser_profile)
  File ""/mnt/owid_live_covid/covid-19-data/scripts/venv/lib/python3.9/site-packages/selenium/webdriver/remote/webdriver.py"", line 252, in start_session
    response = self.execute(Command.NEW_SESSION, parameters)
  File ""/mnt/owid_live_covid/covid-19-data/scripts/venv/lib/python3.9/site-packages/selenium/webdriver/remote/webdriver.py"", line 321, in execute
    self.error_handler.check_response(response)
  File ""/mnt/owid_live_covid/covid-19-data/scripts/venv/lib/python3.9/site-packages/selenium/webdriver/remote/errorhandler.py"", line 242, in check_response
    raise exception_class(message, screen, stacktrace)
selenium.common.exceptions.SessionNotCreatedException: Message: session not created: This version of ChromeDriver only supports Chrome version 103
Current browser version is 105.0.5195.102 with binary path /usr/bin/chromium-browser

","Message: session not created: This version of ChromeDriver only supports Chrome version 103
Current browser version is 105.0.5195.102 with binary path /usr/bin/chromium-browser
"
cowidev.vax.incremental.taiwan,6.51,True,2022-09-19T07:03:00,,
cowidev.vax.incremental.thailand,4.48,True,2022-09-19T07:03:01,,
cowidev.vax.incremental.turkey,1.06,True,2022-09-19T07:03:00,,
cowidev.vax.incremental.united_arab_emirates,,,2022-09-19T07:03:00,,
cowidev.vax.incremental.vietnam,,,2022-09-19T07:03:00,,
cowidev.vax.incremental.who,4.89,True,2022-09-19T07:03:05,,
cowidev.vax.incremental.zambia,0.88,True,2022-09-19T07:03:01,,
